<sdf version='1.7'>
  <model name='arc_delta_onTable'>
    <joint name='base' type='fixed'>
      <pose relative_to='__model__'>0 0 1.359 0 -0 0</pose>
      <parent>world</parent>
      <child>link_0</child>
    </joint>
    <link name='link_0'>
      <pose relative_to='base'>0 0 0 0 -0 0</pose>
      <inertial>
        <pose>0 0 0 0 -0 0</pose>
        <mass>0.48</mass>
        <inertia>
          <ixx>0.003604</ixx>
          <ixy>0</ixy>
          <ixz>0</ixz>
          <iyy>0.003604</iyy>
          <iyz>0</iyz>
          <izz>0.0072</izz>
        </inertia>
      </inertial>
      <collision name='link_0_collision'>
        <pose>-0.147 -0.085 -0.01 0 -0 0</pose>
        <geometry>
          <mesh>
            <scale>0.001 0.001 0.001</scale>
            <uri>model://mara_description/meshes/fixed_base2.dae</uri>
          </mesh>
        </geometry>
        <surface>
          <contact>
            <ode/>
          </contact>
          <friction>
            <ode/>
          </friction>
        </surface>
      </collision>
      <visual name='link_0_visual'>
        <pose>-0.147 -0.085 -0.01 0 -0 0</pose>
        <geometry>
          <mesh>
            <scale>0.001 0.001 0.001</scale>
            <uri>model://mara_description/meshes/fixed_base2.dae</uri>
          </mesh>
        </geometry>
        <material>
          <script>
            <uri>file://media/materials/scripts/gazebo.material</uri>
            <name>Gazebo/Red</name>
          </script>
        </material>
      </visual>
      <visual name='link_0_visual_1'>
        <pose>0 0 0.06 0 -0 0</pose>
        <geometry>
          <box>
            <size>0.05 0.05 0.12</size>
          </box>
        </geometry>
        <material>
          <script>
            <uri>file://media/materials/scripts/gazebo.material</uri>
            <name>Gazebo/Red</name>
          </script>
        </material>
      </visual>
    </link>
    <joint name='motor1' type='revolute'>
      <pose relative_to='link_0'>0 -0.08585 0 0 -0 0</pose>
      <parent>link_0</parent>
      <child>uleg_1</child>
      <axis>
        <xyz>1 0 0</xyz>
        <limit>
          <lower>-1.1</lower>
          <upper>1.1</upper>
          <effort>20</effort>
          <velocity>1.57</velocity>
        </limit>
        <dynamics>
          <spring_reference>0</spring_reference>
          <spring_stiffness>0</spring_stiffness>
        </dynamics>
      </axis>
    </joint>
    <link name='uleg_1'>
      <pose relative_to='motor1'>0 0 0 0 -0 0</pose>
      <inertial>
        <pose>0 -0.071 0 1.5708 -0 0</pose>
        <mass>0.0466</mass>
        <inertia>
          <ixx>0.000165042</ixx>
          <ixy>0</ixy>
          <ixz>0</ixz>
          <iyy>0.000165042</iyy>
          <iyz>0</iyz>
          <izz>1.94167e-05</izz>
        </inertia>
      </inertial>
      <collision name='uleg_1_collision'>
        <pose>0 0.029 0.025 -1.5708 -0 -1.5708</pose>
        <geometry>
          <mesh>
            <scale>0.001 0.001 0.001</scale>
            <uri>model://mara_description/meshes/upper_leg.STL</uri>
          </mesh>
        </geometry>
        <surface>
          <contact>
            <ode/>
          </contact>
          <friction>
            <ode/>
          </friction>
        </surface>
      </collision>
      <visual name='uleg_1_visual'>
        <pose>0 0.029 0.028 -1.5708 -0 -1.5708</pose>
        <geometry>
          <mesh>
            <scale>0.001 0.001 0.001</scale>
            <uri>model://mara_description/meshes/upper_leg.STL</uri>
          </mesh>
        </geometry>
        <material>
          <script>
            <uri>file://media/materials/scripts/gazebo.material</uri>
            <name>Gazebo/Red</name>
          </script>
        </material>
      </visual>
    </link>
    <joint name='uleg1_con' type='revolute'>
      <pose relative_to='uleg_1'>0 -0.2 0 0.534996 -0 0</pose>
      <parent>uleg_1</parent>
      <child>con1</child>
      <axis>
        <xyz>1 0 0</xyz>
        <limit>
          <lower>-1e+16</lower>
          <upper>1e+16</upper>
        </limit>
        <dynamics>
          <spring_reference>0</spring_reference>
          <spring_stiffness>0</spring_stiffness>
        </dynamics>
      </axis>
    </joint>
    <link name='con1'>
      <pose relative_to='uleg1_con'>0 0 0 0 -0 0</pose>
      <inertial>
        <pose>0.005 0 0 0 1.5708 0</pose>
        <mass>0.0173</mass>
        <inertia>
          <ixx>3.60993e-06</ixx>
          <ixy>0</ixy>
          <ixz>0</ixz>
          <iyy>3.60993e-06</iyy>
          <iyz>0</iyz>
          <izz>1.15333e-08</izz>
        </inertia>
      </inertial>
      <collision name='con1_collision'>
        <pose>0.005 0 0 0 1.5708 0</pose>
        <geometry>
          <cylinder>
            <length>0.05</length>
            <radius>0.002</radius>
          </cylinder>
        </geometry>
      </collision>
      <visual name='con1_visual'>
        <pose>0.005 0 0 0 1.5708 0</pose>
        <geometry>
          <cylinder>
            <length>0.05</length>
            <radius>0.002</radius>
          </cylinder>
        </geometry>
      </visual>
    </link>
    <joint name='con2_lleg_1' type='revolute'>
      <pose relative_to='con1'>0.03 0 0 0 -0 0</pose>
      <parent>con1</parent>
      <child>lleg_12</child>
      <axis>
        <xyz>0 1 0</xyz>
        <limit>
          <lower>-1e+16</lower>
          <upper>1e+16</upper>
        </limit>
        <dynamics>
          <spring_reference>0</spring_reference>
          <spring_stiffness>0</spring_stiffness>
        </dynamics>
      </axis>
    </joint>
    <link name='lleg_12'>
      <pose relative_to='con2_lleg_1'>0 0 0 0 -0 0</pose>
      <inertial>
        <pose>0 0 -0.255 0 -0 0</pose>
        <mass>0.04</mass>
        <inertia>
          <ixx>0.000867013</ixx>
          <ixy>0</ixy>
          <ixz>0</ixz>
          <iyy>0.000867013</iyy>
          <iyz>0</iyz>
          <izz>2.66667e-08</izz>
        </inertia>
      </inertial>
      <collision name='lleg_12_collision'>
        <pose>0 0 -0.255 0 -0 0</pose>
        <geometry>
          <cylinder>
            <length>0.51</length>
            <radius>0.002</radius>
          </cylinder>
        </geometry>
      </collision>
      <visual name='lleg_12_visual'>
        <pose>0 0 -0.255 0 -0 0</pose>
        <geometry>
          <cylinder>
            <length>0.51</length>
            <radius>0.002</radius>
          </cylinder>
        </geometry>
      </visual>
    </link>
    <joint name='con13_lleg_1' type='revolute'>
      <pose relative_to='lleg_12'>0 0 -0.51 0 -0 0</pose>
      <parent>lleg_12</parent>
      <child>con13</child>
      <axis>
        <xyz>0 1 0</xyz>
        <limit>
          <lower>-1e+16</lower>
          <upper>1e+16</upper>
        </limit>
        <dynamics>
          <spring_reference>0</spring_reference>
          <spring_stiffness>0</spring_stiffness>
        </dynamics>
      </axis>
    </joint>
    <link name='con13'>
      <pose relative_to='con13_lleg_1'>0 0 0 0 -0 0</pose>
      <inertial>
        <pose>-0.025 0 0 0 1.5708 0</pose>
        <mass>0.0173</mass>
        <inertia>
          <ixx>3.60993e-06</ixx>
          <ixy>0</ixy>
          <ixz>0</ixz>
          <iyy>3.60993e-06</iyy>
          <iyz>0</iyz>
          <izz>1.15333e-08</izz>
        </inertia>
      </inertial>
      <collision name='con13_collision'>
        <pose>-0.025 0 0 0 1.5708 0</pose>
        <geometry>
          <cylinder>
            <length>0.05</length>
            <radius>0.002</radius>
          </cylinder>
        </geometry>
      </collision>
      <visual name='con13_visual'>
        <pose>-0.025 0 0 0 1.5708 0</pose>
        <geometry>
          <cylinder>
            <length>0.05</length>
            <radius>0.002</radius>
          </cylinder>
        </geometry>
      </visual>
    </link>
    <joint name='lleg1_base' type='revolute'>
      <pose relative_to='con13'>0 0 0 -0.5 0 0</pose>
      <parent>con13</parent>
      <child>low_base</child>
      <axis>
        <xyz>1 0 0</xyz>
        <limit>
          <lower>-1e+16</lower>
          <upper>1e+16</upper>
        </limit>
        <dynamics>
          <spring_reference>0</spring_reference>
          <spring_stiffness>0</spring_stiffness>
        </dynamics>
      </axis>
    </joint>
    <link name='low_base'>
      <pose relative_to='lleg1_base'>0 0 0 0 -0 0</pose>
      <inertial>
        <pose>-0.03 0.028893 -0.011436 0 -0 0</pose>
        <mass>0.022</mass>
        <inertia>
          <ixx>0.000209633</ixx>
          <ixy>1.33722e-12</ixy>
          <ixz>1.38094e-11</ixz>
          <iyy>0.000187855</iyy>
          <iyz>-5.56945e-07</iyz>
          <izz>0.000139327</izz>
        </inertia>
      </inertial>
      <collision name='low_base_fixed_joint_lump__robotiq_arg2f_base_link_collision'>
        <pose>-0.03 0.027 0 3.14159 -0.001593 -1.57</pose>
        <geometry>
          <mesh>
            <scale>0.001 0.001 0.001</scale>
            <uri>model://robotiq_140_gripper_description/meshes/GRIPPER_base_axis.dae</uri>
          </mesh>
        </geometry>
        <surface>
          <contact>
            <ode/>
          </contact>
          <friction>
            <ode/>
          </friction>
        </surface>
      </collision>
      <visual name='low_base_visual'>
        <pose>-0.07 -0.015 -0.012 0 -0 0</pose>
        <geometry>
          <mesh>
            <scale>0.001 0.001 0.001</scale>
            <uri>model://mara_description/meshes/Platform.STL</uri>
          </mesh>
        </geometry>
        <material>
          <script>
            <uri>file://media/materials/scripts/gazebo.material</uri>
            <name>Gazebo/Red</name>
          </script>
        </material>
      </visual>
      <visual name='low_base_fixed_joint_lump__robotiq_arg2f_base_link_visual_1'>
        <pose>-0.03 0.027 0 3.14159 -0.001593 -1.57</pose>
        <geometry>
          <mesh>
            <scale>0.001 0.001 0.001</scale>
            <uri>model://robotiq_140_gripper_description/meshes/GRIPPER_base_axis.dae</uri>
          </mesh>
        </geometry>
        <material>
          <script>
            <name>Gazebo/Black</name>
            <uri>file://media/materials/scripts/gazebo.material</uri>
          </script>
        </material>
      </visual>
      <self_collide>0</self_collide>
    </link>
    <joint name='joint_finger' type='revolute'>
      <pose relative_to='low_base'>-0.03 -0.003688 -0.054856 -0.83 0 3.14159</pose>
      <parent>low_base</parent>
      <child>right_outer_knuckle</child>
      <axis>
        <xyz>-1 0 0</xyz>
        <limit>
          <lower>0</lower>
          <upper>0.775</upper>
          <effort>1000</effort>
          <velocity>2</velocity>
        </limit>
        <dynamics>
          <spring_reference>0</spring_reference>
          <spring_stiffness>0</spring_stiffness>
        </dynamics>
      </axis>
    </joint>
    <link name='right_outer_knuckle'>
      <pose relative_to='joint_finger'>0 0 0 0 -0 0</pose>
      <inertial>
        <pose>0.000151 0.027805 0.0026 0 -0 0</pose>
        <mass>0.004</mass>
        <inertia>
          <ixx>2.12647e-05</ixx>
          <ixy>-1.57711e-08</ixy>
          <ixz>-2.10958e-09</ixz>
          <iyy>8.07126e-06</iyy>
          <iyz>5.27865e-06</iyz>
          <izz>1.59612e-05</izz>
        </inertia>
      </inertial>
      <collision name='right_outer_knuckle_collision'>
        <pose>0 0 0 0 -0 0</pose>
        <geometry>
          <mesh>
            <scale>1 1 1</scale>
            <uri>model://robotiq_140_gripper_description/meshes/robotiq_140_right_outer_knuckle.dae</uri>
          </mesh>
        </geometry>
        <surface>
          <contact>
            <ode/>
          </contact>
          <friction>
            <ode/>
          </friction>
        </surface>
      </collision>
      <collision name='right_outer_knuckle_fixed_joint_lump__right_outer_finger_collision_1'>
        <pose>0 0.01822 0.026002 0 -0 0</pose>
        <geometry>
          <mesh>
            <scale>1 1 1</scale>
            <uri>model://robotiq_140_gripper_description/meshes/robotiq_140_right_outer_finger.dae</uri>
          </mesh>
        </geometry>
        <surface>
          <contact>
            <ode/>
          </contact>
          <friction>
            <ode/>
          </friction>
        </surface>
      </collision>
      <visual name='right_outer_knuckle_visual'>
        <pose>0 0 0 0 -0 0</pose>
        <geometry>
          <mesh>
            <scale>1 1 1</scale>
            <uri>model://robotiq_140_gripper_description/meshes/robotiq_140_right_outer_knuckle.dae</uri>
          </mesh>
        </geometry>
        <material>
          <script>
            <name>Gazebo/Grey</name>
            <uri>file://media/materials/scripts/gazebo.material</uri>
          </script>
        </material>
      </visual>
      <visual name='right_outer_knuckle_fixed_joint_lump__right_outer_finger_visual_1'>
        <pose>0 0.01822 0.026002 0 -0 0</pose>
        <geometry>
          <mesh>
            <scale>1 1 1</scale>
            <uri>model://robotiq_140_gripper_description/meshes/robotiq_140_right_outer_finger.dae</uri>
          </mesh>
        </geometry>
        <material>
          <script>
            <name>Gazebo/Black</name>
            <uri>file://media/materials/scripts/gazebo.material</uri>
          </script>
        </material>
      </visual>
      <self_collide>0</self_collide>
    </link>
    <joint name='right_inner_finger_joint' type='revolute'>
      <pose relative_to='right_outer_knuckle'>0 0.099975 -0.002219 -0.725 0 0</pose>
      <parent>right_outer_knuckle</parent>
      <child>right_inner_finger</child>
      <axis>
        <xyz>1 0 0</xyz>
        <limit>
          <lower>0</lower>
          <upper>0.8757</upper>
          <effort>1000</effort>
          <velocity>2</velocity>
        </limit>
        <dynamics>
          <spring_reference>0</spring_reference>
          <spring_stiffness>0</spring_stiffness>
        </dynamics>
      </axis>
    </joint>
    <link name='right_inner_finger'>
      <pose relative_to='right_inner_finger_joint'>0 0 0 0 -0 0</pose>
      <inertial>
        <pose>0 0.031506 -0.017649 0 -0 0</pose>
        <mass>0.002</mass>
        <inertia>
          <ixx>2.71909e-06</ixx>
          <ixy>1.35402e-21</ixy>
          <ixz>-7.18173e-22</ixz>
          <iyy>7.691e-07</iyy>
          <iyz>6.74715e-07</iyz>
          <izz>2.30315e-06</izz>
        </inertia>
      </inertial>
      <collision name='right_inner_finger_collision'>
        <pose>0 0 0 0 -0 0</pose>
        <geometry>
          <mesh>
            <scale>0.001 0.001 0.001</scale>
            <uri>model://robotiq_140_gripper_description/meshes/robotiq_140_right_inner_finger.dae</uri>
          </mesh>
        </geometry>
        <surface>
          <contact>
            <ode/>
          </contact>
          <friction>
            <ode/>
          </friction>
        </surface>
      </collision>
      <visual name='right_inner_finger_visual'>
        <pose>0 0 0 0 -0 0</pose>
        <geometry>
          <mesh>
            <scale>0.001 0.001 0.001</scale>
            <uri>model://robotiq_140_gripper_description/meshes/robotiq_140_right_inner_finger.dae</uri>
          </mesh>
        </geometry>
        <material>
          <script>
            <name>Gazebo/Black</name>
            <uri>file://media/materials/scripts/gazebo.material</uri>
          </script>
        </material>
      </visual>
      <self_collide>0</self_collide>
      <surface>
        <friction>
          <ode>
            <mu>100000</mu>
            <mu2>100000</mu2>
          </ode>
        </friction>
      </surface>
    </link>
    <joint name='left_inner_knuckle_joint' type='revolute'>
      <pose relative_to='low_base'>-0.03 0.039602 -0.06144 -0.853185 0 0</pose>
      <parent>low_base</parent>
      <child>left_inner_knuckle</child>
      <axis>
        <xyz>-1 0 0</xyz>
        <limit>
          <lower>0</lower>
          <upper>0.78</upper>
          <effort>1000</effort>
          <velocity>2</velocity>
        </limit>
        <dynamics>
          <spring_reference>0</spring_reference>
          <spring_stiffness>0</spring_stiffness>
        </dynamics>
      </axis>
    </joint>
    <link name='left_inner_knuckle'>
      <pose relative_to='left_inner_knuckle_joint'>0 0 0 0 -0 0</pose>
      <inertial>
        <pose>0.000123 0.050785 0.00104 0 -0 0</pose>
        <mass>0.002</mass>
        <inertia>
          <ixx>2.6191e-05</ixx>
          <ixy>-2.43617e-07</ixy>
          <ixz>-6.3779e-09</ixz>
          <iyy>2.82702e-06</iyy>
          <iyz>-5.37201e-07</iyz>
          <izz>2.83696e-05</izz>
        </inertia>
      </inertial>
      <visual name='left_inner_knuckle_visual'>
        <pose>0 0 0 0 -0 0</pose>
        <geometry>
          <mesh>
            <scale>1 1 1</scale>
            <uri>model://robotiq_140_gripper_description/meshes/robotiq_140_left_inner_knuckle.dae</uri>
          </mesh>
        </geometry>
        <material>
          <script>
            <name>Gazebo/Black</name>
            <uri>file://media/materials/scripts/gazebo.material</uri>
          </script>
        </material>
      </visual>
      <self_collide>0</self_collide>
    </link>
    <joint name='left_outer_knuckle_joint' type='revolute'>
      <pose relative_to='low_base'>-0.03 0.057514 -0.054954 -0.833185 0 0</pose>
      <parent>low_base</parent>
      <child>left_outer_knuckle</child>
      <axis>
        <xyz>-1 0 0</xyz>
        <limit>
          <lower>0</lower>
          <upper>0.775</upper>
          <effort>1000</effort>
          <velocity>2</velocity>
        </limit>
        <dynamics>
          <spring_reference>0</spring_reference>
          <spring_stiffness>0</spring_stiffness>
        </dynamics>
      </axis>
    </joint>
    <link name='left_outer_knuckle'>
      <pose relative_to='left_outer_knuckle_joint'>0 0 0 0 -0 0</pose>
      <inertial>
        <pose>0.000151 0.027805 0.0026 0 -0 0</pose>
        <mass>0.004</mass>
        <inertia>
          <ixx>2.12647e-05</ixx>
          <ixy>-1.57711e-08</ixy>
          <ixz>-2.10958e-09</ixz>
          <iyy>8.07126e-06</iyy>
          <iyz>5.27865e-06</iyz>
          <izz>1.59612e-05</izz>
        </inertia>
      </inertial>
      <collision name='left_outer_knuckle_collision'>
        <pose>0 0 0 0 -0 0</pose>
        <geometry>
          <mesh>
            <scale>1 1 1</scale>
            <uri>model://robotiq_140_gripper_description/meshes/robotiq_140_left_outer_knuckle.dae</uri>
          </mesh>
        </geometry>
        <surface>
          <contact>
            <ode/>
          </contact>
          <friction>
            <ode/>
          </friction>
        </surface>
      </collision>
      <collision name='left_outer_knuckle_fixed_joint_lump__left_outer_finger_collision_1'>
        <pose>0 0.01822 0.026002 0 -0 0</pose>
        <geometry>
          <mesh>
            <scale>1 1 1</scale>
            <uri>model://robotiq_140_gripper_description/meshes/robotiq_140_left_outer_finger.dae</uri>
          </mesh>
        </geometry>
        <surface>
          <contact>
            <ode/>
          </contact>
          <friction>
            <ode/>
          </friction>
        </surface>
      </collision>
      <visual name='left_outer_knuckle_visual'>
        <pose>0 0 0 0 -0 0</pose>
        <geometry>
          <mesh>
            <scale>1 1 1</scale>
            <uri>model://robotiq_140_gripper_description/meshes/robotiq_140_left_outer_knuckle.dae</uri>
          </mesh>
        </geometry>
        <material>
          <script>
            <name>Gazebo/Grey</name>
            <uri>file://media/materials/scripts/gazebo.material</uri>
          </script>
        </material>
      </visual>
      <visual name='left_outer_knuckle_fixed_joint_lump__left_outer_finger_visual_1'>
        <pose>0 0.01822 0.026002 0 -0 0</pose>
        <geometry>
          <mesh>
            <scale>1 1 1</scale>
            <uri>model://robotiq_140_gripper_description/meshes/robotiq_140_left_outer_finger.dae</uri>
          </mesh>
        </geometry>
        <material>
          <script>
            <name>Gazebo/Black</name>
            <uri>file://media/materials/scripts/gazebo.material</uri>
          </script>
        </material>
      </visual>
      <self_collide>0</self_collide>
    </link>
    <joint name='left_inner_finger_joint' type='revolute'>
      <pose relative_to='left_outer_knuckle'>0 0.099975 -0.002219 -0.725 0 0</pose>
      <parent>left_outer_knuckle</parent>
      <child>left_inner_finger</child>
      <axis>
        <xyz>1 0 0</xyz>
        <limit>
          <lower>0</lower>
          <upper>0.8757</upper>
          <effort>1000</effort>
          <velocity>2</velocity>
        </limit>
        <dynamics>
          <spring_reference>0</spring_reference>
          <spring_stiffness>0</spring_stiffness>
        </dynamics>
      </axis>
    </joint>
    <link name='left_inner_finger'>
      <pose relative_to='left_inner_finger_joint'>0 0 0 0 -0 0</pose>
      <inertial>
        <pose>0 0.031506 -0.017649 0 -0 0</pose>
        <mass>0.002</mass>
        <inertia>
          <ixx>2.71909e-06</ixx>
          <ixy>1.35402e-21</ixy>
          <ixz>-7.18173e-22</ixz>
          <iyy>7.691e-07</iyy>
          <iyz>6.74715e-07</iyz>
          <izz>2.30315e-06</izz>
        </inertia>
      </inertial>
      <collision name='left_inner_finger_collision'>
        <pose>0 0 0 0 -0 0</pose>
        <geometry>
          <mesh>
            <scale>0.001 0.001 0.001</scale>
            <uri>model://robotiq_140_gripper_description/meshes/robotiq_140_left_inner_finger.dae</uri>
          </mesh>
        </geometry>
        <surface>
          <contact>
            <ode/>
          </contact>
          <friction>
            <ode/>
          </friction>
        </surface>
      </collision>
      <visual name='left_inner_finger_visual'>
        <pose>0 0 0 0 -0 0</pose>
        <geometry>
          <mesh>
            <scale>0.001 0.001 0.001</scale>
            <uri>model://robotiq_140_gripper_description/meshes/robotiq_140_left_inner_finger.dae</uri>
          </mesh>
        </geometry>
        <material>
          <script>
            <name>Gazebo/Black</name>
            <uri>file://media/materials/scripts/gazebo.material</uri>
          </script>
        </material>
      </visual>
      <self_collide>0</self_collide>
      <surface>
        <friction>
          <ode>
            <mu>100000</mu>
            <mu2>100000</mu2>
          </ode>
        </friction>
      </surface>
    </link>
    <joint name='right_inner_knuckle_joint' type='revolute'>
      <pose relative_to='low_base'>-0.03 0.014202 -0.0614 -0.85 -0 -3.14159</pose>
      <parent>low_base</parent>
      <child>right_inner_knuckle</child>
      <axis>
        <xyz>-1 0 0</xyz>
        <limit>
          <lower>0</lower>
          <upper>0.78</upper>
          <effort>1000</effort>
          <velocity>2</velocity>
        </limit>
        <dynamics>
          <spring_reference>0</spring_reference>
          <spring_stiffness>0</spring_stiffness>
        </dynamics>
      </axis>
    </joint>
    <link name='right_inner_knuckle'>
      <pose relative_to='right_inner_knuckle_joint'>0 0 0 0 -0 0</pose>
      <inertial>
        <pose>0.000123 0.050785 0.00104 0 -0 0</pose>
        <mass>0.002</mass>
        <inertia>
          <ixx>2.6191e-05</ixx>
          <ixy>-2.43617e-07</ixy>
          <ixz>-6.3779e-09</ixz>
          <iyy>2.82702e-06</iyy>
          <iyz>-5.37201e-07</iyz>
          <izz>2.83696e-05</izz>
        </inertia>
      </inertial>
      <visual name='right_inner_knuckle_visual'>
        <pose>0 0 0 0 -0 0</pose>
        <geometry>
          <mesh>
            <scale>1 1 1</scale>
            <uri>model://robotiq_140_gripper_description/meshes/robotiq_140_right_inner_knuckle.dae</uri>
          </mesh>
        </geometry>
        <material>
          <script>
            <name>Gazebo/Black</name>
            <uri>file://media/materials/scripts/gazebo.material</uri>
          </script>
        </material>
      </visual>
      <self_collide>0</self_collide>
    </link>
    <joint name='con_lleg_1' type='revolute'>
      <pose relative_to='con1'>-0.02 0 0 0 -0 0</pose>
      <parent>con1</parent>
      <child>lleg_1</child>
      <axis>
        <xyz>0 1 0</xyz>
        <limit>
          <lower>-1e+16</lower>
          <upper>1e+16</upper>
        </limit>
        <dynamics>
          <spring_reference>0</spring_reference>
          <spring_stiffness>0</spring_stiffness>
        </dynamics>
      </axis>
    </joint>
    <link name='lleg_1'>
      <pose relative_to='con_lleg_1'>0 0 0 0 -0 0</pose>
      <inertial>
        <pose>0 0 -0.255 0 -0 0</pose>
        <mass>0.04</mass>
        <inertia>
          <ixx>0.000867013</ixx>
          <ixy>0</ixy>
          <ixz>0</ixz>
          <iyy>0.000867013</iyy>
          <iyz>0</iyz>
          <izz>2.66667e-08</izz>
        </inertia>
      </inertial>
      <collision name='lleg_1_collision'>
        <pose>0 0 -0.255 0 -0 0</pose>
        <geometry>
          <cylinder>
            <length>0.51</length>
            <radius>0.002</radius>
          </cylinder>
        </geometry>
      </collision>
      <visual name='lleg_1_visual'>
        <pose>0 0 -0.255 0 -0 0</pose>
        <geometry>
          <cylinder>
            <length>0.51</length>
            <radius>0.002</radius>
          </cylinder>
        </geometry>
      </visual>
    </link>
    <joint name='motor2' type='revolute'>
      <pose relative_to='link_0'>-0.075 0.047925 0 0 0 -2.0944</pose>
      <parent>link_0</parent>
      <child>uleg_2</child>
      <axis>
        <xyz>1 0 0</xyz>
        <limit>
          <lower>-1.1</lower>
          <upper>1.1</upper>
          <effort>20</effort>
          <velocity>1.57</velocity>
        </limit>
        <dynamics>
          <spring_reference>0</spring_reference>
          <spring_stiffness>0</spring_stiffness>
        </dynamics>
      </axis>
    </joint>
    <link name='uleg_2'>
      <pose relative_to='motor2'>0 0 0 0 -0 0</pose>
      <inertial>
        <pose>0 -0.071 0 1.5708 -0 0</pose>
        <mass>0.0466</mass>
        <inertia>
          <ixx>0.000165042</ixx>
          <ixy>0</ixy>
          <ixz>0</ixz>
          <iyy>0.000165042</iyy>
          <iyz>0</iyz>
          <izz>1.94167e-05</izz>
        </inertia>
      </inertial>
      <collision name='uleg_2_collision'>
        <pose>0 0.029 0.025 -1.5708 -0 -1.5708</pose>
        <geometry>
          <mesh>
            <scale>0.001 0.001 0.001</scale>
            <uri>model://mara_description/meshes/upper_leg.STL</uri>
          </mesh>
        </geometry>
        <surface>
          <contact>
            <ode/>
          </contact>
          <friction>
            <ode/>
          </friction>
        </surface>
      </collision>
      <visual name='uleg_2_visual'>
        <pose>0 0.029 0.028 -1.5708 -0 -1.5708</pose>
        <geometry>
          <mesh>
            <scale>0.001 0.001 0.001</scale>
            <uri>model://mara_description/meshes/upper_leg.STL</uri>
          </mesh>
        </geometry>
        <material>
          <script>
            <uri>file://media/materials/scripts/gazebo.material</uri>
            <name>Gazebo/Red</name>
          </script>
        </material>
      </visual>
    </link>
    <joint name='uleg2_con' type='revolute'>
      <pose relative_to='uleg_2'>0 -0.2 0 0.534996 -0 0</pose>
      <parent>uleg_2</parent>
      <child>con2</child>
      <axis>
        <xyz>1 0 0</xyz>
        <limit>
          <lower>-1e+16</lower>
          <upper>1e+16</upper>
        </limit>
        <dynamics>
          <spring_reference>0</spring_reference>
          <spring_stiffness>0</spring_stiffness>
        </dynamics>
      </axis>
    </joint>
    <link name='con2'>
      <pose relative_to='uleg2_con'>0 0 0 0 -0 0</pose>
      <inertial>
        <pose>0.005 0 0 0 1.5708 0</pose>
        <mass>0.0173</mass>
        <inertia>
          <ixx>3.60993e-06</ixx>
          <ixy>0</ixy>
          <ixz>0</ixz>
          <iyy>3.60993e-06</iyy>
          <iyz>0</iyz>
          <izz>1.15333e-08</izz>
        </inertia>
      </inertial>
      <collision name='con2_collision'>
        <pose>0.005 0 0 0 1.5708 0</pose>
        <geometry>
          <cylinder>
            <length>0.05</length>
            <radius>0.002</radius>
          </cylinder>
        </geometry>
      </collision>
      <visual name='con2_visual'>
        <pose>0.005 0 0 0 1.5708 0</pose>
        <geometry>
          <cylinder>
            <length>0.05</length>
            <radius>0.002</radius>
          </cylinder>
        </geometry>
      </visual>
    </link>
    <joint name='con2_lleg_2' type='revolute'>
      <pose relative_to='con2'>0.03 0 0 0 -0 0</pose>
      <parent>con2</parent>
      <child>lleg_22</child>
      <axis>
        <xyz>0 1 0</xyz>
        <limit>
          <lower>-1e+16</lower>
          <upper>1e+16</upper>
        </limit>
        <dynamics>
          <spring_reference>0</spring_reference>
          <spring_stiffness>0</spring_stiffness>
        </dynamics>
      </axis>
    </joint>
    <link name='lleg_22'>
      <pose relative_to='con2_lleg_2'>0 0 0 0 -0 0</pose>
      <inertial>
        <pose>0 0 -0.255 0 -0 0</pose>
        <mass>0.04</mass>
        <inertia>
          <ixx>0.000867013</ixx>
          <ixy>0</ixy>
          <ixz>0</ixz>
          <iyy>0.000867013</iyy>
          <iyz>0</iyz>
          <izz>2.66667e-08</izz>
        </inertia>
      </inertial>
      <collision name='lleg_22_collision'>
        <pose>0 0 -0.255 0 -0 0</pose>
        <geometry>
          <cylinder>
            <length>0.51</length>
            <radius>0.002</radius>
          </cylinder>
        </geometry>
      </collision>
      <visual name='lleg_22_visual'>
        <pose>0 0 -0.255 0 -0 0</pose>
        <geometry>
          <cylinder>
            <length>0.51</length>
            <radius>0.002</radius>
          </cylinder>
        </geometry>
      </visual>
    </link>
    <joint name='con23_lleg_2' type='revolute'>
      <pose relative_to='lleg_22'>0 0 -0.51 0 -0 0</pose>
      <parent>lleg_22</parent>
      <child>con23</child>
      <axis>
        <xyz>0 1 0</xyz>
        <limit>
          <lower>-1e+16</lower>
          <upper>1e+16</upper>
        </limit>
        <dynamics>
          <spring_reference>0</spring_reference>
          <spring_stiffness>0</spring_stiffness>
        </dynamics>
      </axis>
    </joint>
    <link name='con23'>
      <pose relative_to='con23_lleg_2'>0 0 0 0 -0 0</pose>
      <inertial>
        <pose>-0.025 0 0 0 1.5708 0</pose>
        <mass>0.0173</mass>
        <inertia>
          <ixx>3.60993e-06</ixx>
          <ixy>0</ixy>
          <ixz>0</ixz>
          <iyy>3.60993e-06</iyy>
          <iyz>0</iyz>
          <izz>1.15333e-08</izz>
        </inertia>
      </inertial>
      <collision name='con23_collision'>
        <pose>-0.025 0 0 0 1.5708 0</pose>
        <geometry>
          <cylinder>
            <length>0.05</length>
            <radius>0.002</radius>
          </cylinder>
        </geometry>
      </collision>
      <visual name='con23_visual'>
        <pose>-0.025 0 0 0 1.5708 0</pose>
        <geometry>
          <cylinder>
            <length>0.05</length>
            <radius>0.002</radius>
          </cylinder>
        </geometry>
      </visual>
    </link>
    <joint name='con_lleg_2' type='revolute'>
      <pose relative_to='con2'>-0.02 0 0 0 -0 0</pose>
      <parent>con2</parent>
      <child>lleg_2</child>
      <axis>
        <xyz>0 1 0</xyz>
        <limit>
          <lower>-1e+16</lower>
          <upper>1e+16</upper>
        </limit>
        <dynamics>
          <spring_reference>0</spring_reference>
          <spring_stiffness>0</spring_stiffness>
        </dynamics>
      </axis>
    </joint>
    <link name='lleg_2'>
      <pose relative_to='con_lleg_2'>0 0 0 0 -0 0</pose>
      <inertial>
        <pose>0 0 -0.255 0 -0 0</pose>
        <mass>0.04</mass>
        <inertia>
          <ixx>0.000867013</ixx>
          <ixy>0</ixy>
          <ixz>0</ixz>
          <iyy>0.000867013</iyy>
          <iyz>0</iyz>
          <izz>2.66667e-08</izz>
        </inertia>
      </inertial>
      <collision name='lleg_2_collision'>
        <pose>0 0 -0.255 0 -0 0</pose>
        <geometry>
          <cylinder>
            <length>0.51</length>
            <radius>0.002</radius>
          </cylinder>
        </geometry>
      </collision>
      <visual name='lleg_2_visual'>
        <pose>0 0 -0.255 0 -0 0</pose>
        <geometry>
          <cylinder>
            <length>0.51</length>
            <radius>0.002</radius>
          </cylinder>
        </geometry>
      </visual>
    </link>
    <joint name='motor3' type='revolute'>
      <pose relative_to='link_0'>0.075 0.042925 0 0 -0 2.0944</pose>
      <parent>link_0</parent>
      <child>uleg_3</child>
      <axis>
        <xyz>1 0 0</xyz>
        <limit>
          <lower>-1.1</lower>
          <upper>1.1</upper>
          <effort>20</effort>
          <velocity>1.57</velocity>
        </limit>
        <dynamics>
          <spring_reference>0</spring_reference>
          <spring_stiffness>0</spring_stiffness>
        </dynamics>
      </axis>
    </joint>
    <link name='uleg_3'>
      <pose relative_to='motor3'>0 0 0 0 -0 0</pose>
      <inertial>
        <pose>0 -0.071 0 1.5708 -0 0</pose>
        <mass>0.0466</mass>
        <inertia>
          <ixx>0.000165042</ixx>
          <ixy>0</ixy>
          <ixz>0</ixz>
          <iyy>0.000165042</iyy>
          <iyz>0</iyz>
          <izz>1.94167e-05</izz>
        </inertia>
      </inertial>
      <collision name='uleg_3_collision'>
        <pose>0 0.029 0.025 -1.5708 -0 -1.5708</pose>
        <geometry>
          <mesh>
            <scale>0.001 0.001 0.001</scale>
            <uri>model://mara_description/meshes/upper_leg.STL</uri>
          </mesh>
        </geometry>
        <surface>
          <contact>
            <ode/>
          </contact>
          <friction>
            <ode/>
          </friction>
        </surface>
      </collision>
      <visual name='uleg_3_visual'>
        <pose>0 0.029 0.028 -1.5708 -0 -1.5708</pose>
        <geometry>
          <mesh>
            <scale>0.001 0.001 0.001</scale>
            <uri>model://mara_description/meshes/upper_leg.STL</uri>
          </mesh>
        </geometry>
        <material>
          <script>
            <uri>file://media/materials/scripts/gazebo.material</uri>
            <name>Gazebo/Red</name>
          </script>
        </material>
      </visual>
    </link>
    <joint name='uleg3_con' type='revolute'>
      <pose relative_to='uleg_3'>0 -0.2 0 0.534996 -0 0</pose>
      <parent>uleg_3</parent>
      <child>con3</child>
      <axis>
        <xyz>1 0 0</xyz>
        <limit>
          <lower>-1e+16</lower>
          <upper>1e+16</upper>
        </limit>
        <dynamics>
          <spring_reference>0</spring_reference>
          <spring_stiffness>0</spring_stiffness>
        </dynamics>
      </axis>
    </joint>
    <link name='con3'>
      <pose relative_to='uleg3_con'>0 0 0 0 -0 0</pose>
      <inertial>
        <pose>0.005 0 0 0 1.5708 0</pose>
        <mass>0.0173</mass>
        <inertia>
          <ixx>3.60993e-06</ixx>
          <ixy>0</ixy>
          <ixz>0</ixz>
          <iyy>3.60993e-06</iyy>
          <iyz>0</iyz>
          <izz>1.15333e-08</izz>
        </inertia>
      </inertial>
      <collision name='con3_collision'>
        <pose>0.005 0 0 0 1.5708 0</pose>
        <geometry>
          <cylinder>
            <length>0.05</length>
            <radius>0.002</radius>
          </cylinder>
        </geometry>
      </collision>
      <visual name='con3_visual'>
        <pose>0.005 0 0 0 1.5708 0</pose>
        <geometry>
          <cylinder>
            <length>0.05</length>
            <radius>0.002</radius>
          </cylinder>
        </geometry>
      </visual>
    </link>
    <joint name='con2_lleg_3' type='revolute'>
      <pose relative_to='con3'>0.03 0 0 0 -0 0</pose>
      <parent>con3</parent>
      <child>lleg_32</child>
      <axis>
        <xyz>0 1 0</xyz>
        <limit>
          <lower>-1e+16</lower>
          <upper>1e+16</upper>
        </limit>
        <dynamics>
          <spring_reference>0</spring_reference>
          <spring_stiffness>0</spring_stiffness>
        </dynamics>
      </axis>
    </joint>
    <link name='lleg_32'>
      <pose relative_to='con2_lleg_3'>0 0 0 0 -0 0</pose>
      <inertial>
        <pose>0 0 -0.255 0 -0 0</pose>
        <mass>0.04</mass>
        <inertia>
          <ixx>0.000867013</ixx>
          <ixy>0</ixy>
          <ixz>0</ixz>
          <iyy>0.000867013</iyy>
          <iyz>0</iyz>
          <izz>2.66667e-08</izz>
        </inertia>
      </inertial>
      <collision name='lleg_32_collision'>
        <pose>0 0 -0.255 0 -0 0</pose>
        <geometry>
          <cylinder>
            <length>0.51</length>
            <radius>0.002</radius>
          </cylinder>
        </geometry>
      </collision>
      <visual name='lleg_32_visual'>
        <pose>0 0 -0.255 0 -0 0</pose>
        <geometry>
          <cylinder>
            <length>0.51</length>
            <radius>0.002</radius>
          </cylinder>
        </geometry>
      </visual>
    </link>
    <joint name='con33_lleg_3' type='revolute'>
      <pose relative_to='lleg_32'>0 0 -0.51 0 -0 0</pose>
      <parent>lleg_32</parent>
      <child>con33</child>
      <axis>
        <xyz>0 1 0</xyz>
        <limit>
          <lower>-1e+16</lower>
          <upper>1e+16</upper>
        </limit>
        <dynamics>
          <spring_reference>0</spring_reference>
          <spring_stiffness>0</spring_stiffness>
        </dynamics>
      </axis>
    </joint>
    <link name='con33'>
      <pose relative_to='con33_lleg_3'>0 0 0 0 -0 0</pose>
      <inertial>
        <pose>-0.025 0 0 0 1.5708 0</pose>
        <mass>0.0173</mass>
        <inertia>
          <ixx>3.60993e-06</ixx>
          <ixy>0</ixy>
          <ixz>0</ixz>
          <iyy>3.60993e-06</iyy>
          <iyz>0</iyz>
          <izz>1.15333e-08</izz>
        </inertia>
      </inertial>
      <collision name='con33_collision'>
        <pose>-0.025 0 0 0 1.5708 0</pose>
        <geometry>
          <cylinder>
            <length>0.05</length>
            <radius>0.002</radius>
          </cylinder>
        </geometry>
      </collision>
      <visual name='con33_visual'>
        <pose>-0.025 0 0 0 1.5708 0</pose>
        <geometry>
          <cylinder>
            <length>0.05</length>
            <radius>0.002</radius>
          </cylinder>
        </geometry>
      </visual>
    </link>
    <joint name='con_lleg_3' type='revolute'>
      <pose relative_to='con3'>-0.02 0 0 0 -0 0</pose>
      <parent>con3</parent>
      <child>lleg_3</child>
      <axis>
        <xyz>0 1 0</xyz>
        <limit>
          <lower>-1e+16</lower>
          <upper>1e+16</upper>
        </limit>
        <dynamics>
          <spring_reference>0</spring_reference>
          <spring_stiffness>0</spring_stiffness>
        </dynamics>
      </axis>
    </joint>
    <link name='lleg_3'>
      <pose relative_to='con_lleg_3'>0 0 0 0 -0 0</pose>
      <inertial>
        <pose>0 0 -0.255 0 -0 0</pose>
        <mass>0.04</mass>
        <inertia>
          <ixx>0.000867013</ixx>
          <ixy>0</ixy>
          <ixz>0</ixz>
          <iyy>0.000867013</iyy>
          <iyz>0</iyz>
          <izz>2.66667e-08</izz>
        </inertia>
      </inertial>
      <collision name='lleg_3_collision'>
        <pose>0 0 -0.255 0 -0 0</pose>
        <geometry>
          <cylinder>
            <length>0.51</length>
            <radius>0.002</radius>
          </cylinder>
        </geometry>
      </collision>
      <visual name='lleg_3_visual'>
        <pose>0 0 -0.255 0 -0 0</pose>
        <geometry>
          <cylinder>
            <length>0.51</length>
            <radius>0.002</radius>
          </cylinder>
        </geometry>
      </visual>
    </link>
    <joint name='world_to_table_joint' type='fixed'>
      <pose relative_to='__model__'>0 0 0 0 -0 0</pose>
      <parent>world</parent>
      <child>table</child>
    </joint>
    <link name='table'>
      <pose relative_to='world_to_table_joint'>0 0 0 0 -0 0</pose>
      <inertial>
        <pose>0 0 0 0 -0 0</pose>
        <mass>1e-05</mass>
        <inertia>
          <ixx>0.001</ixx>
          <ixy>0</ixy>
          <ixz>0</ixz>
          <iyy>0.001</iyy>
          <iyz>0</iyz>
          <izz>0.001</izz>
        </inertia>
      </inertial>
      <collision name='table_collision'>
        <pose>0 0 0.6 0 -0 0</pose>
        <geometry>
          <box>
            <size>1.5 1 0.05</size>
          </box>
        </geometry>
        <surface>
          <contact>
            <ode/>
          </contact>
          <friction>
            <ode/>
          </friction>
        </surface>
      </collision>
      <visual name='table_visual'>
        <pose>0 0 0.6 0 -0 0</pose>
        <geometry>
          <mesh>
            <scale>1.5 1 0.05</scale>
            <uri>model://mara_description/urdf/table.obj</uri>
          </mesh>
        </geometry>
        <material>
          <script>
            <name>Gazebo/Brown</name>
            <uri>file://media/materials/scripts/gazebo.material</uri>
          </script>
        </material>
      </visual>
      <visual name='table_visual_1'>
        <pose>-0.65 -0.4 0.29 0 -0 0</pose>
        <geometry>
          <mesh>
            <scale>0.1 0.1 0.58</scale>
            <uri>model://mara_description/urdf/table.obj</uri>
          </mesh>
        </geometry>
        <material>
          <script>
            <name>Gazebo/Brown</name>
            <uri>file://media/materials/scripts/gazebo.material</uri>
          </script>
        </material>
      </visual>
      <visual name='table_visual_2'>
        <pose>-0.65 0.4 0.29 0 -0 0</pose>
        <geometry>
          <mesh>
            <scale>0.1 0.1 0.58</scale>
            <uri>model://mara_description/urdf/table.obj</uri>
          </mesh>
        </geometry>
        <material>
          <script>
            <name>Gazebo/Brown</name>
            <uri>file://media/materials/scripts/gazebo.material</uri>
          </script>
        </material>
      </visual>
      <visual name='table_visual_3'>
        <pose>0.65 -0.4 0.29 0 -0 0</pose>
        <geometry>
          <mesh>
            <scale>0.1 0.1 0.58</scale>
            <uri>model://mara_description/urdf/table.obj</uri>
          </mesh>
        </geometry>
        <material>
          <script>
            <name>Gazebo/Brown</name>
            <uri>file://media/materials/scripts/gazebo.material</uri>
          </script>
        </material>
      </visual>
      <visual name='table_visual_4'>
        <pose>0.65 0.4 0.29 0 -0 0</pose>
        <geometry>
          <mesh>
            <scale>0.1 0.1 0.58</scale>
            <uri>model://mara_description/urdf/table.obj</uri>
          </mesh>
        </geometry>
        <material>
          <script>
            <name>Gazebo/Brown</name>
            <uri>file://media/materials/scripts/gazebo.material</uri>
          </script>
        </material>
      </visual>
      <self_collide>1</self_collide>
      <kinematic>1</kinematic>
    </link>
    <joint name='lleg2_base' type='revolute'>
      <child>con23</child>
      <parent>low_base</parent>
      <pose>0 0 0 0 -0 0</pose>
      <axis>
        <xyz>1 0 0</xyz>
        <limit>
          <lower>-100</lower>
          <upper>100</upper>
        </limit>
        <dynamics>
          <spring_reference>0</spring_reference>
          <spring_stiffness>0</spring_stiffness>
          <damping>0</damping>
          <friction>0.0003</friction>
        </dynamics>
        <use_parent_model_frame>0</use_parent_model_frame>
      </axis>
    </joint>
    <joint name='lleg3_base' type='revolute'>
      <child>con33</child>
      <parent>low_base</parent>
      <pose>0 0 0 0 -0 0</pose>
      <axis>
        <xyz>1 0 0</xyz>
        <limit>
          <lower>-100</lower>
          <upper>100</upper>
        </limit>
        <dynamics>
          <spring_reference>0</spring_reference>
          <spring_stiffness>0</spring_stiffness>
          <damping>0</damping>
          <friction>0.0003</friction>
        </dynamics>
        <use_parent_model_frame>0</use_parent_model_frame>
      </axis>
    </joint>
    <joint name='con13_lleg_12' type='revolute'>
      <child>con13</child>
      <parent>lleg_1</parent>
      <pose>-0.05 0 0 0 -0 0</pose>
      <axis>
        <xyz>0 1 0</xyz>
        <limit>
          <lower>-100</lower>
          <upper>100</upper>
        </limit>
        <dynamics>
          <spring_reference>0</spring_reference>
          <spring_stiffness>0</spring_stiffness>
          <damping>0</damping>
          <friction>0.0003</friction>
        </dynamics>
        <use_parent_model_frame>0</use_parent_model_frame>
      </axis>
    </joint>
    <joint name='con23_lleg_22' type='revolute'>
      <child>con23</child>
      <parent>lleg_2</parent>
      <pose>-0.05 0 0 0 -0 0</pose>
      <axis>
        <xyz>0 1 0</xyz>
        <limit>
          <lower>-100</lower>
          <upper>100</upper>
        </limit>
        <dynamics>
          <spring_reference>0</spring_reference>
          <spring_stiffness>0</spring_stiffness>
          <damping>0</damping>
          <friction>0.0003</friction>
        </dynamics>
        <use_parent_model_frame>0</use_parent_model_frame>
      </axis>
    </joint>
    <joint name='con33_lleg_32' type='revolute'>
      <child>con33</child>
      <parent>lleg_3</parent>
      <pose>-0.05 0 0 0 -0 0</pose>
      <axis>
        <xyz>0 1 0</xyz>
        <limit>
          <lower>-100</lower>
          <upper>100</upper>
        </limit>
        <dynamics>
          <spring_reference>0</spring_reference>
          <spring_stiffness>0</spring_stiffness>
          <damping>0</damping>
          <friction>0.0003</friction>
        </dynamics>
        <use_parent_model_frame>0</use_parent_model_frame>
      </axis>
    </joint>
    <model name='sharp_box1'>
      <static>0</static>
      <pose>1.4e-05 0.209779 0.7 0 -0 0</pose>
      <link name='link'>
        <inertial>
          <mass>0.01</mass>
          <inertia>
            <ixx>1</ixx>
            <ixy>0</ixy>
            <ixz>0</ixz>
            <iyy>1</iyy>
            <iyz>0</iyz>
            <izz>1</izz>
          </inertia>
        </inertial>
        <collision name='collision'>
          <geometry>
            <box>
              <size>0.025 0.01 0.06</size>
            </box>
          </geometry>
          <surface>
            <friction>
              <ode>
                <mu>1.01</mu>
                <mu2>1.01</mu2>
                <fdir1>0 0 0</fdir1>
                <slip1>0</slip1>
                <slip2>0</slip2>
              </ode>
            </friction>
            <contact>
              <ode>
                <soft_cfm>0</soft_cfm>
                <soft_erp>0.2</soft_erp>
                <kp>100000</kp>
                <kd>1</kd>
                <max_vel>100</max_vel>
                <min_depth>0.001</min_depth>
              </ode>
            </contact>
          </surface>
        </collision>
        <visual name='visual'>
          <cast_shadows>1</cast_shadows>
          <geometry>
            <box>
              <size>0.025 0.01 0.06</size>
            </box>
          </geometry>
          <material>
            <script>
              <uri>file://media/materials/scripts/gazebo.material</uri>
              <name>Gazebo/Grey</name>
            </script>
          </material>
        </visual>
      </link>
    </model>
    <model name='sharp_box2'>
      <static>0</static>
      <pose>-0.099998 0.099997 0.7 0 -0 0</pose>
      <link name='link'>
        <inertial>
          <mass>0.001</mass>
          <inertia>
            <ixx>1</ixx>
            <ixy>0</ixy>
            <ixz>0</ixz>
            <iyy>1</iyy>
            <iyz>0</iyz>
            <izz>1</izz>
          </inertia>
        </inertial>
        <collision name='collision'>
          <geometry>
            <box>
              <size>0.025 0.01 0.06</size>
            </box>
          </geometry>
          <surface>
            <friction>
              <ode>
                <mu>100000</mu>
                <mu2>100000</mu2>
              </ode>
            </friction>
          </surface>
        </collision>
        <visual name='visual'>
          <cast_shadows>1</cast_shadows>
          <geometry>
            <box>
              <size>0.025 0.01 0.06</size>
            </box>
          </geometry>
          <material>
            <script>
              <uri>file://media/materials/scripts/gazebo.material</uri>
              <name>Gazebo/Grey</name>
            </script>
          </material>
        </visual>
      </link>
    </model>
    <model name='sharp_box3'>
      <static>0</static>
      <pose>0.099998 0.150002 0.7 0 -0 0</pose>
      <link name='link'>
        <inertial>
          <mass>0.001</mass>
          <inertia>
            <ixx>1</ixx>
            <ixy>0</ixy>
            <ixz>0</ixz>
            <iyy>1</iyy>
            <iyz>0</iyz>
            <izz>1</izz>
          </inertia>
        </inertial>
        <collision name='collision'>
          <geometry>
            <box>
              <size>0.025 0.01 0.06</size>
            </box>
          </geometry>
          <surface>
            <friction>
              <ode>
                <mu>100000</mu>
                <mu2>100000</mu2>
              </ode>
            </friction>
          </surface>
        </collision>
        <visual name='visual'>
          <cast_shadows>1</cast_shadows>
          <geometry>
            <box>
              <size>0.025 0.01 0.06</size>
            </box>
          </geometry>
          <material>
            <script>
              <uri>file://media/materials/scripts/gazebo.material</uri>
              <name>Gazebo/Grey</name>
            </script>
          </material>
        </visual>
      </link>
    </model>
    <model name='sharp_box4'>
      <static>0</static>
      <pose>0.089907 9.6e-05 0.7 0 -0 0</pose>
      <link name='link'>
        <inertial>
          <mass>0.001</mass>
          <inertia>
            <ixx>1</ixx>
            <ixy>0</ixy>
            <ixz>0</ixz>
            <iyy>1</iyy>
            <iyz>0</iyz>
            <izz>1</izz>
          </inertia>
        </inertial>
        <collision name='collision'>
          <geometry>
            <box>
              <size>0.025 0.01 0.06</size>
            </box>
          </geometry>
          <surface>
            <friction>
              <ode>
                <mu>100000</mu>
                <mu2>100000</mu2>
              </ode>
            </friction>
          </surface>
        </collision>
        <visual name='visual'>
          <cast_shadows>1</cast_shadows>
          <geometry>
            <box>
              <size>0.025 0.01 0.06</size>
            </box>
          </geometry>
          <material>
            <script>
              <uri>file://media/materials/scripts/gazebo.material</uri>
              <name>Gazebo/Grey</name>
            </script>
          </material>
        </visual>
      </link>
    </model>
    <model name='sharp_box5'>
      <static>0</static>
      <pose>-0.009371 0.05808 0.7 0 -0 0</pose>
      <link name='link'>
        <inertial>
          <mass>0.001</mass>
          <inertia>
            <ixx>1</ixx>
            <ixy>0</ixy>
            <ixz>0</ixz>
            <iyy>1</iyy>
            <iyz>0</iyz>
            <izz>1</izz>
          </inertia>
        </inertial>
        <collision name='collision'>
          <geometry>
            <box>
              <size>0.025 0.01 0.06</size>
            </box>
          </geometry>
          <surface>
            <friction>
              <ode>
                <mu>100000</mu>
                <mu2>100000</mu2>
              </ode>
            </friction>
          </surface>
        </collision>
        <visual name='visual'>
          <cast_shadows>1</cast_shadows>
          <geometry>
            <box>
              <size>0.025 0.01 0.06</size>
            </box>
          </geometry>
          <material>
            <script>
              <uri>file://media/materials/scripts/gazebo.material</uri>
              <name>Gazebo/Grey</name>
            </script>
          </material>
        </visual>
      </link>
    </model>
    <frame name='bowl::__model__' attached_to='bowl::link'>
      <pose relative_to='__model__'>0.28 -0.07 0.7 0 -0 0</pose>
    </frame>
    <link name='bowl::link'>
      <inertial>
        <pose>0 0 0.0175 0 -0 0</pose>
        <mass>0.1</mass>
        <inertia>
          <ixx>0.000250308</ixx>
          <ixy>0</ixy>
          <ixz>0</ixz>
          <iyy>0.000250308</iyy>
          <iyz>0</iyz>
          <izz>0.0004802</izz>
        </inertia>
      </inertial>
      <collision name='collision'>
        <pose>0 0 0.0175 0 -0 0</pose>
        <geometry>
          <cylinder>
            <radius>0.098</radius>
            <length>0.035</length>
          </cylinder>
        </geometry>
      </collision>
      <visual name='visual'>
        <geometry>
          <mesh>
            <uri>model://bowl/meshes/bowl.dae</uri>
          </mesh>
        </geometry>
      </visual>
      <pose relative_to='bowl::__model__'>0 0 0 0 -0 0</pose>
    </link>
    <static>0</static>
    <joint name='left_inner_finger_knuckle_joint' type='revolute'>
      <pose>0 0.006 -0.018 0 -0 0</pose>
      <parent>mara::left_inner_knuckle</parent>
      <child>mara::left_inner_finger</child>
      <axis>
        <xyz>1 0 0</xyz>
        <limit>
          <lower>-0.8</lower>
          <upper>0.8</upper>
          <velocity>2</velocity>
          <effort>1000</effort>
        </limit>
      </axis>
    </joint>
    <joint name='right_inner_finger_knuckle_joint' type='revolute'>
      <pose>0 0.006 -0.018 0 -0 0</pose>
      <parent>mara::right_inner_knuckle</parent>
      <child>mara::right_inner_finger</child>
      <axis>
        <xyz>-1 0 0</xyz>
        <limit>
          <lower>-0.8</lower>
          <upper>0.8</upper>
          <velocity>2</velocity>
          <effort>1000</effort>
        </limit>
      </axis>
    </joint>
    <plugin name='hrim_actuation_gripper_000000000004' filename='librobotiq_gripper_gazebo_plugin.so'>
      <joint>left_inner_knuckle_joint</joint>
      <joint>left_outer_knuckle_joint</joint>
      <joint>right_inner_knuckle_joint</joint>
      <joint>joint_finger</joint>
    </plugin>
    <plugin name='mara_joint_state' filename='libgazebo_ros_joint_state_publisher.so'>
      <ros>
        <argument>~/out:=joint_states</argument>
      </ros>
      <update_rate>25</update_rate>
      <joint_name>joint_finger</joint_name>
    </plugin>
    <static>0</static>
    <plugin name='hrim_actuation_servomotor_00000000000' filename='libmara_gazebo_joint_training_plugin_3dof.so'>
      <ros/>
      <axis1>motor2</axis1>
      <axis2>motor1</axis2>
      <axis3>motor3</axis3>
    </plugin>
  </model>
</sdf>
