<sdf version='1.7'>
  <model name='delta'>
    <joint name='world_base_joint' type='fixed'>
      <pose relative_to='__model__'>1 0 0 0 -0 0</pose>
      <parent>world</parent>
      <child>base_link</child>
    </joint>
    <link name='base_link'>
      <pose relative_to='world_base_joint'>0 0 0 0 -0 0</pose>
      <inertial>
        <pose>0 0 0.00635 0 -0 0</pose>
        <mass>12</mass>
        <inertia>
          <ixx>0.0371243</ixx>
          <ixy>0</ixy>
          <ixz>0</ixz>
          <iyy>0.0371243</iyy>
          <iyz>0</iyz>
          <izz>0.073926</izz>
        </inertia>
      </inertial>
      <collision name='base_link_collision'>
        <pose>0 0 0.00635 0 -0 0</pose>
        <geometry>
          <cylinder>
            <length>0.0127</length>
            <radius>0.111</radius>
          </cylinder>
        </geometry>
        <surface>
          <contact>
            <ode/>
          </contact>
          <friction>
            <ode/>
          </friction>
        </surface>
      </collision>
      <visual name='base_link_visual'>
        <pose>0 0 0.00635 0 -0 0</pose>
        <geometry>
          <cylinder>
            <length>0.0127</length>
            <radius>0.111</radius>
          </cylinder>
        </geometry>
        <material>
          <script>
            <name>Gazebo/Green</name>
            <uri>file://media/materials/scripts/gazebo.material</uri>
          </script>
        </material>
      </visual>
    </link>
    <joint name='base_arm_1_joint' type='revolute'>
      <pose relative_to='base_link'>-0.115 0 0.0254 0 -0 0</pose>
      <parent>base_link</parent>
      <child>arm_1_link</child>
      <axis>
        <xyz>0 1 0</xyz>
        <limit>
          <lower>-1.5708</lower>
          <upper>1.5708</upper>
          <effort>100</effort>
          <velocity>100</velocity>
        </limit>
        <dynamics>
          <damping>4</damping>
          <friction>4</friction>
          <spring_reference>0</spring_reference>
          <spring_stiffness>0</spring_stiffness>
        </dynamics>
      </axis>
    </joint>
    <link name='arm_1_link'>
      <pose relative_to='base_arm_1_joint'>0 0 0 0 -0 0</pose>
      <inertial>
        <pose>-0.09 0 0 0 -0 0</pose>
        <mass>6</mass>
        <inertia>
          <ixx>0.000944661</ixx>
          <ixy>0</ixy>
          <ixz>0</ixz>
          <iyy>0.018037</iyy>
          <iyz>0</iyz>
          <izz>0.0171327</izz>
        </inertia>
      </inertial>
      <collision name='arm_1_link_collision'>
        <pose>-0.09 0 0 0 -0 0</pose>
        <geometry>
          <box>
            <size>0.185 0.00635 0.043</size>
          </box>
        </geometry>
      </collision>
      <visual name='arm_1_link_visual'>
        <pose>-0.09 0 0 0 -0 0</pose>
        <geometry>
          <box>
            <size>0.185 0.00635 0.043</size>
          </box>
        </geometry>
      </visual>
    </link>
    <joint name='arm_forearm_1_1_joint' type='revolute'>
      <pose relative_to='arm_1_link'>-0.19 0 0 0 -0 0</pose>
      <parent>arm_1_link</parent>
      <child>virtual_link_1_1</child>
      <axis>
        <xyz>1 0 0</xyz>
        <limit>
          <lower>-0.418879</lower>
          <upper>0.418879</upper>
          <effort>100</effort>
          <velocity>100</velocity>
        </limit>
        <dynamics>
          <damping>0</damping>
          <friction>0.003</friction>
          <spring_reference>0</spring_reference>
          <spring_stiffness>0</spring_stiffness>
        </dynamics>
      </axis>
    </joint>
    <link name='virtual_link_1_1'>
      <pose relative_to='arm_forearm_1_1_joint'>0 0 0 0 -0 0</pose>
      <inertial>
        <pose>0 0 0 0 -0 0</pose>
        <mass>0.1</mass>
        <inertia>
          <ixx>1.66667e-06</ixx>
          <ixy>0</ixy>
          <ixz>0</ixz>
          <iyy>1.66667e-06</iyy>
          <iyz>0</iyz>
          <izz>1.66667e-06</izz>
        </inertia>
      </inertial>
    </link>
    <joint name='arm_forearm_1_2_joint' type='revolute'>
      <pose relative_to='virtual_link_1_1'>0 0 0 0 -0 0</pose>
      <parent>virtual_link_1_1</parent>
      <child>virtual_link_1_2</child>
      <axis>
        <xyz>0 1 0</xyz>
        <limit>
          <lower>-3.14159</lower>
          <upper>3.14159</upper>
          <effort>100</effort>
          <velocity>100</velocity>
        </limit>
        <dynamics>
          <damping>0</damping>
          <friction>0.003</friction>
          <spring_reference>0</spring_reference>
          <spring_stiffness>0</spring_stiffness>
        </dynamics>
      </axis>
    </joint>
    <link name='virtual_link_1_2'>
      <pose relative_to='arm_forearm_1_2_joint'>0 0 0 0 -0 0</pose>
      <inertial>
        <pose>0 0 0 0 -0 0</pose>
        <mass>0.1</mass>
        <inertia>
          <ixx>1.66667e-06</ixx>
          <ixy>0</ixy>
          <ixz>0</ixz>
          <iyy>1.66667e-06</iyy>
          <iyz>0</iyz>
          <izz>1.66667e-06</izz>
        </inertia>
      </inertial>
    </link>
    <joint name='arm_forearm_1_3_joint' type='revolute'>
      <pose relative_to='virtual_link_1_2'>0 0 0 0 -0 0</pose>
      <parent>virtual_link_1_2</parent>
      <child>forearm_1_link</child>
      <axis>
        <xyz>0 0 1</xyz>
        <limit>
          <lower>-0.418879</lower>
          <upper>0.418879</upper>
          <effort>100</effort>
          <velocity>100</velocity>
        </limit>
        <dynamics>
          <damping>0</damping>
          <friction>0.003</friction>
          <spring_reference>0</spring_reference>
          <spring_stiffness>0</spring_stiffness>
        </dynamics>
      </axis>
    </joint>
    <link name='forearm_1_link'>
      <pose relative_to='arm_forearm_1_3_joint'>0 0 0 0 -0 0</pose>
      <inertial>
        <pose>0 0 0 0 -0 0</pose>
        <mass>4</mass>
        <inertia>
          <ixx>0.122513</ixx>
          <ixy>0</ixy>
          <ixz>0</ixz>
          <iyy>0.122513</iyy>
          <iyz>0</iyz>
          <izz>0.245</izz>
        </inertia>
      </inertial>
      <collision name='forearm_1_link_collision'>
        <pose>0 0 0.175 0 -0 0</pose>
        <geometry>
          <cylinder>
            <length>0.35</length>
            <radius>0.00635</radius>
          </cylinder>
        </geometry>
      </collision>
      <visual name='forearm_1_link_visual'>
        <pose>0 0 0.175 0 -0 0</pose>
        <geometry>
          <cylinder>
            <length>0.35</length>
            <radius>0.00635</radius>
          </cylinder>
        </geometry>
      </visual>
    </link>
    <joint name='arm_forearm_1_4_joint' type='revolute'>
      <pose relative_to='forearm_1_link'>0 0 0.35635 0 -0 0</pose>
      <parent>forearm_1_link</parent>
      <child>virtual_link_1_4</child>
      <axis>
        <xyz>1 0 0</xyz>
        <limit>
          <lower>-0.418879</lower>
          <upper>0.418879</upper>
          <effort>100</effort>
          <velocity>100</velocity>
        </limit>
        <dynamics>
          <spring_reference>0</spring_reference>
          <spring_stiffness>0</spring_stiffness>
        </dynamics>
      </axis>
    </joint>
    <link name='virtual_link_1_4'>
      <pose relative_to='arm_forearm_1_4_joint'>0 0 0 0 -0 0</pose>
      <inertial>
        <pose>0 0 0 0 -0 0</pose>
        <mass>0.1</mass>
        <inertia>
          <ixx>1.66667e-06</ixx>
          <ixy>0</ixy>
          <ixz>0</ixz>
          <iyy>1.66667e-06</iyy>
          <iyz>0</iyz>
          <izz>1.66667e-06</izz>
        </inertia>
      </inertial>
    </link>
    <joint name='arm_forearm_1_5_joint' type='revolute'>
      <pose relative_to='virtual_link_1_4'>0 0 0 0 -0 0</pose>
      <parent>virtual_link_1_4</parent>
      <child>virtual_link_1_5</child>
      <axis>
        <xyz>0 1 0</xyz>
        <limit>
          <lower>-3.14159</lower>
          <upper>3.14159</upper>
          <effort>100</effort>
          <velocity>100</velocity>
        </limit>
        <dynamics>
          <spring_reference>0</spring_reference>
          <spring_stiffness>0</spring_stiffness>
        </dynamics>
      </axis>
    </joint>
    <link name='virtual_link_1_5'>
      <pose relative_to='arm_forearm_1_5_joint'>0 0 0 0 -0 0</pose>
      <inertial>
        <pose>0 0 0 0 -0 0</pose>
        <mass>0.1</mass>
        <inertia>
          <ixx>1.66667e-06</ixx>
          <ixy>0</ixy>
          <ixz>0</ixz>
          <iyy>1.66667e-06</iyy>
          <iyz>0</iyz>
          <izz>1.66667e-06</izz>
        </inertia>
      </inertial>
    </link>
    <joint name='arm_forearm_1_6_joint' type='revolute'>
      <pose relative_to='virtual_link_1_5'>-0.035 0 0 0 -0 0</pose>
      <parent>virtual_link_1_5</parent>
      <child>mobile_platform</child>
      <axis>
        <xyz>0 0 1</xyz>
        <limit>
          <lower>-0.418879</lower>
          <upper>0.418879</upper>
          <effort>100</effort>
          <velocity>100</velocity>
        </limit>
        <dynamics>
          <spring_reference>0</spring_reference>
          <spring_stiffness>0</spring_stiffness>
        </dynamics>
      </axis>
    </joint>
    <link name='mobile_platform'>
      <pose relative_to='arm_forearm_1_6_joint'>0 0 0 0 -0 0</pose>
      <inertial>
        <pose>0 0 -0.003175 0 -0 0</pose>
        <mass>4</mass>
        <inertia>
          <ixx>0.00123844</ixx>
          <ixy>0</ixy>
          <ixz>0</ixz>
          <iyy>0.00123844</iyy>
          <iyz>0</iyz>
          <izz>0.00245</izz>
        </inertia>
      </inertial>
      <collision name='mobile_platform_collision'>
        <pose>0 0 -0.003175 0 -0 0</pose>
        <geometry>
          <cylinder>
            <length>0.00635</length>
            <radius>0.035</radius>
          </cylinder>
        </geometry>
      </collision>
      <visual name='mobile_platform_visual'>
        <pose>0 0 -0.003175 0 -0 0</pose>
        <geometry>
          <cylinder>
            <length>0.00635</length>
            <radius>0.035</radius>
          </cylinder>
        </geometry>
      </visual>
    </link>
    <joint name='base_arm_2_joint' type='revolute'>
      <pose relative_to='base_link'>0.055 0.096 0.0254 0 0 -2.0944</pose>
      <parent>base_link</parent>
      <child>arm_2_link</child>
      <axis>
        <xyz>0 1 0</xyz>
        <limit>
          <lower>-1.5708</lower>
          <upper>1.5708</upper>
          <effort>100</effort>
          <velocity>100</velocity>
        </limit>
        <dynamics>
          <damping>4</damping>
          <friction>4</friction>
          <spring_reference>0</spring_reference>
          <spring_stiffness>0</spring_stiffness>
        </dynamics>
      </axis>
    </joint>
    <link name='arm_2_link'>
      <pose relative_to='base_arm_2_joint'>0 0 0 0 -0 0</pose>
      <inertial>
        <pose>-0.09 0 0 0 -0 0</pose>
        <mass>6</mass>
        <inertia>
          <ixx>0.000944661</ixx>
          <ixy>0</ixy>
          <ixz>0</ixz>
          <iyy>0.018037</iyy>
          <iyz>0</iyz>
          <izz>0.0171327</izz>
        </inertia>
      </inertial>
      <collision name='arm_2_link_collision'>
        <pose>-0.09 0 0 0 -0 0</pose>
        <geometry>
          <box>
            <size>0.185 0.00635 0.043</size>
          </box>
        </geometry>
      </collision>
      <visual name='arm_2_link_visual'>
        <pose>-0.09 0 0 0 -0 0</pose>
        <geometry>
          <box>
            <size>0.185 0.00635 0.043</size>
          </box>
        </geometry>
      </visual>
    </link>
    <joint name='arm_forearm_2_1_joint' type='revolute'>
      <pose relative_to='arm_2_link'>-0.19 0 0 0 -0 0</pose>
      <parent>arm_2_link</parent>
      <child>virtual_link_2_1</child>
      <axis>
        <xyz>1 0 0</xyz>
        <limit>
          <lower>-0.418879</lower>
          <upper>0.418879</upper>
          <effort>100</effort>
          <velocity>100</velocity>
        </limit>
        <dynamics>
          <spring_reference>0</spring_reference>
          <spring_stiffness>0</spring_stiffness>
        </dynamics>
      </axis>
    </joint>
    <link name='virtual_link_2_1'>
      <pose relative_to='arm_forearm_2_1_joint'>0 0 0 0 -0 0</pose>
      <inertial>
        <pose>0 0 0 0 -0 0</pose>
        <mass>0.1</mass>
        <inertia>
          <ixx>1.66667e-06</ixx>
          <ixy>0</ixy>
          <ixz>0</ixz>
          <iyy>1.66667e-06</iyy>
          <iyz>0</iyz>
          <izz>1.66667e-06</izz>
        </inertia>
      </inertial>
    </link>
    <joint name='arm_forearm_2_2_joint' type='revolute'>
      <pose relative_to='virtual_link_2_1'>0 0 0 0 -0 0</pose>
      <parent>virtual_link_2_1</parent>
      <child>virtual_link_2_2</child>
      <axis>
        <xyz>0 1 0</xyz>
        <limit>
          <lower>-3.14159</lower>
          <upper>3.14159</upper>
          <effort>100</effort>
          <velocity>100</velocity>
        </limit>
        <dynamics>
          <spring_reference>0</spring_reference>
          <spring_stiffness>0</spring_stiffness>
        </dynamics>
      </axis>
    </joint>
    <link name='virtual_link_2_2'>
      <pose relative_to='arm_forearm_2_2_joint'>0 0 0 0 -0 0</pose>
      <inertial>
        <pose>0 0 0 0 -0 0</pose>
        <mass>0.1</mass>
        <inertia>
          <ixx>1.66667e-06</ixx>
          <ixy>0</ixy>
          <ixz>0</ixz>
          <iyy>1.66667e-06</iyy>
          <iyz>0</iyz>
          <izz>1.66667e-06</izz>
        </inertia>
      </inertial>
    </link>
    <joint name='arm_forearm_2_3_joint' type='revolute'>
      <pose relative_to='virtual_link_2_2'>0 0 0 0 -0 0</pose>
      <parent>virtual_link_2_2</parent>
      <child>forearm_2_link</child>
      <axis>
        <xyz>0 0 1</xyz>
        <limit>
          <lower>-0.418879</lower>
          <upper>0.418879</upper>
          <effort>100</effort>
          <velocity>100</velocity>
        </limit>
        <dynamics>
          <spring_reference>0</spring_reference>
          <spring_stiffness>0</spring_stiffness>
        </dynamics>
      </axis>
    </joint>
    <link name='forearm_2_link'>
      <pose relative_to='arm_forearm_2_3_joint'>0 0 0 0 -0 0</pose>
      <inertial>
        <pose>0 0 0 0 -0 0</pose>
        <mass>4</mass>
        <inertia>
          <ixx>0.122513</ixx>
          <ixy>0</ixy>
          <ixz>0</ixz>
          <iyy>0.122513</iyy>
          <iyz>0</iyz>
          <izz>0.245</izz>
        </inertia>
      </inertial>
      <collision name='forearm_2_link_collision'>
        <pose>0 0 0.175 0 -0 0</pose>
        <geometry>
          <cylinder>
            <length>0.35</length>
            <radius>0.00635</radius>
          </cylinder>
        </geometry>
      </collision>
      <visual name='forearm_2_link_visual'>
        <pose>0 0 0.175 0 -0 0</pose>
        <geometry>
          <cylinder>
            <length>0.35</length>
            <radius>0.00635</radius>
          </cylinder>
        </geometry>
      </visual>
    </link>
    <joint name='arm_forearm_2_4_joint' type='revolute'>
      <pose relative_to='forearm_2_link'>0 0 0.35635 0 -0 0</pose>
      <parent>forearm_2_link</parent>
      <child>virtual_link_2_4</child>
      <axis>
        <xyz>1 0 0</xyz>
        <limit>
          <lower>-0.418879</lower>
          <upper>0.418879</upper>
          <effort>100</effort>
          <velocity>100</velocity>
        </limit>
        <dynamics>
          <spring_reference>0</spring_reference>
          <spring_stiffness>0</spring_stiffness>
        </dynamics>
      </axis>
    </joint>
    <link name='virtual_link_2_4'>
      <pose relative_to='arm_forearm_2_4_joint'>0 0 0 0 -0 0</pose>
      <inertial>
        <pose>0 0 0 0 -0 0</pose>
        <mass>0.1</mass>
        <inertia>
          <ixx>1.66667e-06</ixx>
          <ixy>0</ixy>
          <ixz>0</ixz>
          <iyy>1.66667e-06</iyy>
          <iyz>0</iyz>
          <izz>1.66667e-06</izz>
        </inertia>
      </inertial>
    </link>
    <joint name='arm_forearm_2_5_joint' type='revolute'>
      <pose relative_to='virtual_link_2_4'>0 0 0 0 -0 0</pose>
      <parent>virtual_link_2_4</parent>
      <child>virtual_link_2_5</child>
      <axis>
        <xyz>0 1 0</xyz>
        <limit>
          <lower>-3.14159</lower>
          <upper>3.14159</upper>
          <effort>100</effort>
          <velocity>100</velocity>
        </limit>
        <dynamics>
          <spring_reference>0</spring_reference>
          <spring_stiffness>0</spring_stiffness>
        </dynamics>
      </axis>
    </joint>
    <link name='virtual_link_2_5'>
      <pose relative_to='arm_forearm_2_5_joint'>0 0 0 0 -0 0</pose>
      <inertial>
        <pose>0 0 0 0 -0 0</pose>
        <mass>0.1</mass>
        <inertia>
          <ixx>1.66667e-06</ixx>
          <ixy>0</ixy>
          <ixz>0</ixz>
          <iyy>1.66667e-06</iyy>
          <iyz>0</iyz>
          <izz>1.66667e-06</izz>
        </inertia>
      </inertial>
    </link>
    <joint name='base_arm_3_joint' type='revolute'>
      <pose relative_to='base_link'>0.055 -0.096 0.0254 0 -0 2.0944</pose>
      <parent>base_link</parent>
      <child>arm_3_link</child>
      <axis>
        <xyz>0 1 0</xyz>
        <limit>
          <lower>-1.5708</lower>
          <upper>1.5708</upper>
          <effort>100</effort>
          <velocity>100</velocity>
        </limit>
        <dynamics>
          <damping>4</damping>
          <friction>4</friction>
          <spring_reference>0</spring_reference>
          <spring_stiffness>0</spring_stiffness>
        </dynamics>
      </axis>
    </joint>
    <link name='arm_3_link'>
      <pose relative_to='base_arm_3_joint'>0 0 0 0 -0 0</pose>
      <inertial>
        <pose>-0.09 0 0 0 -0 0</pose>
        <mass>6</mass>
        <inertia>
          <ixx>0.000944661</ixx>
          <ixy>0</ixy>
          <ixz>0</ixz>
          <iyy>0.018037</iyy>
          <iyz>0</iyz>
          <izz>0.0171327</izz>
        </inertia>
      </inertial>
      <collision name='arm_3_link_collision'>
        <pose>-0.09 0 0 0 -0 0</pose>
        <geometry>
          <box>
            <size>0.185 0.00635 0.043</size>
          </box>
        </geometry>
      </collision>
      <visual name='arm_3_link_visual'>
        <pose>-0.09 0 0 0 -0 0</pose>
        <geometry>
          <box>
            <size>0.185 0.00635 0.043</size>
          </box>
        </geometry>
      </visual>
    </link>
    <joint name='arm_forearm_3_1_joint' type='revolute'>
      <pose relative_to='arm_3_link'>-0.19 0 0 0 -0 0</pose>
      <parent>arm_3_link</parent>
      <child>virtual_link_3_1</child>
      <axis>
        <xyz>1 0 0</xyz>
        <limit>
          <lower>-0.418879</lower>
          <upper>0.418879</upper>
          <effort>100</effort>
          <velocity>100</velocity>
        </limit>
        <dynamics>
          <spring_reference>0</spring_reference>
          <spring_stiffness>0</spring_stiffness>
        </dynamics>
      </axis>
    </joint>
    <link name='virtual_link_3_1'>
      <pose relative_to='arm_forearm_3_1_joint'>0 0 0 0 -0 0</pose>
      <inertial>
        <pose>0 0 0 0 -0 0</pose>
        <mass>0.1</mass>
        <inertia>
          <ixx>1.66667e-06</ixx>
          <ixy>0</ixy>
          <ixz>0</ixz>
          <iyy>1.66667e-06</iyy>
          <iyz>0</iyz>
          <izz>1.66667e-06</izz>
        </inertia>
      </inertial>
    </link>
    <joint name='arm_forearm_3_2_joint' type='revolute'>
      <pose relative_to='virtual_link_3_1'>0 0 0 0 -0 0</pose>
      <parent>virtual_link_3_1</parent>
      <child>virtual_link_3_2</child>
      <axis>
        <xyz>0 1 0</xyz>
        <limit>
          <lower>-3.14159</lower>
          <upper>3.14159</upper>
          <effort>100</effort>
          <velocity>100</velocity>
        </limit>
        <dynamics>
          <spring_reference>0</spring_reference>
          <spring_stiffness>0</spring_stiffness>
        </dynamics>
      </axis>
    </joint>
    <link name='virtual_link_3_2'>
      <pose relative_to='arm_forearm_3_2_joint'>0 0 0 0 -0 0</pose>
      <inertial>
        <pose>0 0 0 0 -0 0</pose>
        <mass>0.1</mass>
        <inertia>
          <ixx>1.66667e-06</ixx>
          <ixy>0</ixy>
          <ixz>0</ixz>
          <iyy>1.66667e-06</iyy>
          <iyz>0</iyz>
          <izz>1.66667e-06</izz>
        </inertia>
      </inertial>
    </link>
    <joint name='arm_forearm_3_3_joint' type='revolute'>
      <pose relative_to='virtual_link_3_2'>0 0 0 0 -0 0</pose>
      <parent>virtual_link_3_2</parent>
      <child>forearm_3_link</child>
      <axis>
        <xyz>0 0 1</xyz>
        <limit>
          <lower>-0.418879</lower>
          <upper>0.418879</upper>
          <effort>100</effort>
          <velocity>100</velocity>
        </limit>
        <dynamics>
          <spring_reference>0</spring_reference>
          <spring_stiffness>0</spring_stiffness>
        </dynamics>
      </axis>
    </joint>
    <link name='forearm_3_link'>
      <pose relative_to='arm_forearm_3_3_joint'>0 0 0 0 -0 0</pose>
      <inertial>
        <pose>0 0 0 0 -0 0</pose>
        <mass>4</mass>
        <inertia>
          <ixx>0.122513</ixx>
          <ixy>0</ixy>
          <ixz>0</ixz>
          <iyy>0.122513</iyy>
          <iyz>0</iyz>
          <izz>0.245</izz>
        </inertia>
      </inertial>
      <collision name='forearm_3_link_collision'>
        <pose>0 0 0.175 0 -0 0</pose>
        <geometry>
          <cylinder>
            <length>0.35</length>
            <radius>0.00635</radius>
          </cylinder>
        </geometry>
      </collision>
      <visual name='forearm_3_link_visual'>
        <pose>0 0 0.175 0 -0 0</pose>
        <geometry>
          <cylinder>
            <length>0.35</length>
            <radius>0.00635</radius>
          </cylinder>
        </geometry>
      </visual>
    </link>
    <joint name='arm_forearm_2_6_joint' type='revolute'>
      <parent>__default__</parent>
      <child>__default__</child>
      <axis>
        <xyz>0 0 1</xyz>
        <limit>
          <lower>-1e+16</lower>
          <upper>1e+16</upper>
        </limit>
      </axis>
      <origin xyz='-0.0175 0.03031 0.0'/>
      <limit effort='100.0' lower='-0.41887902047863906' upper='0.41887902047863906' velocity='100.0'/>
    </joint>
    <plugin name='gazebo_ros_joint_state_publisher' filename='libgazebo_ros_joint_state_publisher.so'>
      <update_rate>20</update_rate>
      <joint_name>base_arm_1_joint</joint_name>
      <joint_name>arm_forearm_1_1_joint</joint_name>
      <joint_name>arm_forearm_1_2_joint</joint_name>
      <joint_name>arm_forearm_1_3_joint</joint_name>
      <joint_name>arm_forearm_1_4_joint</joint_name>
      <joint_name>arm_forearm_1_5_joint</joint_name>
      <joint_name>arm_forearm_1_6_joint</joint_name>
      <joint_name>base_arm_2_joint</joint_name>
      <joint_name>arm_forearm_2_1_joint</joint_name>
      <joint_name>arm_forearm_2_2_joint</joint_name>
      <joint_name>arm_forearm_2_3_joint</joint_name>
      <joint_name>arm_forearm_2_4_joint</joint_name>
      <joint_name>arm_forearm_2_5_joint</joint_name>
      <joint_name>arm_forearm_2_6_joint</joint_name>
      <joint_name>base_arm_3_joint</joint_name>
      <joint_name>arm_forearm_3_1_joint</joint_name>
      <joint_name>arm_forearm_3_2_joint</joint_name>
      <joint_name>arm_forearm_3_3_joint</joint_name>
    </plugin>
    <static>0</static>
    <plugin name='gazebo_ros_joint_pose_trajectory' filename='libgazebo_ros_joint_pose_trajectory.so'>
      <update_rate>20</update_rate>
    </plugin>
  </model>
</sdf>
