<?xml version="1.0" ?>
<!-- =================================================================================== -->
<!-- |    This document was autogenerated by xacro from delta.urdf.xacro               | -->
<!-- |    EDITING THIS FILE BY HAND IS NOT RECOMMENDED                                 | -->
<!-- =================================================================================== -->
<!-- Revolute-Revolute Manipulator -->
<robot name="delta">
  <!-- base and end links -->
  <!-- Upper link -->
  <physics type="ode">
    <max_step_size>0.001</max_step_size>
    <real_time_factor>0.1</real_time_factor>
    <real_time_update_rate>1000</real_time_update_rate>
    <gravity>0 0 -9.8</gravity>
  </physics>
  <gazebo>
    <plugin filename="libgazebo_ros_control.so" name="gazebo_ros_control">
      <robotNamespace/>
      <robotSimType>gazebo_ros_control/DefaultRobotHWSim</robotSimType>
      <legacyModeNS>true</legacyModeNS>
    </plugin>
  </gazebo>
  <gazebo reference="base_link">
    <material>Gazebo/Orange</material>
    <selfCollide>false</selfCollide>
  </gazebo>
  <gazebo reference="end_link">
    <material>Gazebo/Orange</material>
    <selfCollide>false</selfCollide>
  </gazebo>
  <transmission name="front_delta_arm_joint_trans">
    <type>transmission_interface/SimpleTransmission</type>
    <joint name="front_delta_arm_joint">
      <hardwareInterface>hardware_interface/EffortJointInterface</hardwareInterface>
    </joint>
    <actuator name="front_delta_arm_joint_motor">
      <hardwareInterface>hardware_interface/EffortJointInterface</hardwareInterface>
      <mechanicalReduction>1</mechanicalReduction>
    </actuator>
  </transmission>
  <transmission name="right_delta_arm_joint_trans">
    <type>transmission_interface/SimpleTransmission</type>
    <joint name="right_delta_arm_joint">
      <hardwareInterface>hardware_interface/EffortJointInterface</hardwareInterface>
    </joint>
    <actuator name="right_delta_arm_joint_motor">
      <hardwareInterface>hardware_interface/EffortJointInterface</hardwareInterface>
      <mechanicalReduction>1</mechanicalReduction>
    </actuator>
  </transmission>
  <transmission name="left_delta_arm_joint_trans">
    <type>transmission_interface/SimpleTransmission</type>
    <joint name="left_delta_arm_joint">
      <hardwareInterface>hardware_interface/EffortJointInterface</hardwareInterface>
    </joint>
    <actuator name="left_delta_arm_joint_motor">
      <hardwareInterface>hardware_interface/EffortJointInterface</hardwareInterface>
      <mechanicalReduction>1</mechanicalReduction>
    </actuator>
  </transmission>
  <material name="black">
    <color rgba="0.0 0.0 0.0 1.0"/>
  </material>
  <material name="blue">
    <color rgba="0.0 0.0 0.8 1.0"/>
  </material>
  <material name="green">
    <color rgba="0.0 0.8 0.0 1.0"/>
  </material>
  <material name="grey">
    <color rgba="0.2 0.2 0.2 1.0"/>
  </material>
  <material name="orange">
    <color rgba="1.0 0.4235294117647059 0.0392156862745098 1.0"/>
  </material>
  <material name="brown">
    <color rgba="0.8705882352941177 0.8117647058823529 0.7647058823529411 1.0"/>
  </material>
  <material name="red">
    <color rgba="0.8 0.0 0.0 1.0"/>
  </material>
  <material name="white">
    <color rgba="1.0 1.0 1.0 1.0"/>
  </material>
  <!-- Used for fixing robot to Gazebo 'base_link' -->
  <link name="world"/>
  <joint name="fixed" type="fixed">
    <parent link="world"/>
    <child link="base_link"/>
    <origin rpy="0 0 0" xyz="0 0 2"/>
  </joint>
  <link name="base_link">
    <collision>
      <origin rpy="0 0 0" xyz="0 0 0"/>
      <geometry>
        <cylinder length="0.05" radius="0.1"/>
      </geometry>
    </collision>
    <visual>
      <origin rpy="0 0 0" xyz="0 0 0"/>
      <geometry>
        <cylinder length="0.05" radius="0.1"/>
      </geometry>
      <material name="orange">
        <color rgba="1.0 0.4235294117647059 0.0392156862745098 1.0"/>
      </material>
    </visual>
    <inertial>
      <origin rpy="0 0 0" xyz="0 0 0"/>
      <mass value="1"/>
      <inertia ixx="0.1" ixy="0.0" ixz="0.0" iyy="0.1" iyz="0.0" izz="0.1"/>
    </inertial>
  </link>
  <link name="front_upper_link">
    <collision>
      <origin rpy="0 0 0" xyz="0.1 0 0"/>
      <geometry>
        <box size="0.2 0.04 0.04"/>
      </geometry>
    </collision>
    <visual>
      <origin rpy="0 0 0" xyz="0.1 0 0"/>
      <geometry>
        <box size="0.2 0.04 0.04"/>
      </geometry>
      <material name="black">
        <color rgba="0.0 0.0 0.0 1.0"/>
      </material>
    </visual>
    <inertial>
      <origin rpy="0 0 0" xyz="0 0 0.1"/>
      <mass value="0.02"/>
      <inertia ixx="5.333333333333334e-06" ixy="0.0" ixz="0.0" iyy="6.933333333333334e-05" iyz="0.0" izz="6.933333333333334e-05"/>
    </inertial>
  </link>
  <joint name="front_upper_joint" type="continuous">
    <parent link="front_upper_link"/>
    <child link="front_lower_top_link"/>
    <origin rpy="0 0.5235987755982988 0" xyz="0.2 0 0"/>
    <axis xyz="0 1 0"/>
  </joint>
  <link name="front_lower_top_link">
    <collision>
      <origin rpy="0 0 0" xyz="0 0 0"/>
      <geometry>
        <box size="0.01 0.06 0.01"/>
      </geometry>
    </collision>
    <visual>
      <origin rpy="0 0 0" xyz="0 0 0"/>
      <geometry>
        <box size="0.01 0.06 0.01"/>
      </geometry>
      <material name="grey">
        <color rgba="0.2 0.2 0.2 1.0"/>
      </material>
    </visual>
    <inertial>
      <origin rpy="0 0 0" xyz="0 0 0"/>
      <mass value="0.02"/>
      <inertia ixx="6.166666666666666e-06" ixy="0.0" ixz="0.0" iyy="3.3333333333333335e-07" iyz="0.0" izz="6.166666666666666e-06"/>
    </inertial>
  </link>
  <joint name="front_lower_top_rignt_joint" type="continuous">
    <parent link="front_lower_top_link"/>
    <child link="front_lower_right_link"/>
    <origin rpy="0 0 0" xyz="0 -0.03 0"/>
    <axis xyz="1 0 0"/>
  </joint>
  <link name="front_lower_right_link">
    <collision>
      <origin rpy="0 0 0" xyz="0 0 -0.25"/>
      <geometry>
        <box size="0.01 0.01 0.5"/>
      </geometry>
    </collision>
    <visual>
      <origin rpy="0 0 0" xyz="0 0 -0.25"/>
      <geometry>
        <box size="0.01 0.01 0.5"/>
      </geometry>
      <material name="grey">
        <color rgba="0.2 0.2 0.2 1.0"/>
      </material>
    </visual>
    <inertial>
      <origin rpy="0 0 0" xyz="0 0 -0.25"/>
      <mass value="0.02"/>
      <inertia ixx="0.00041683333333333335" ixy="0.0" ixz="0.0" iyy="0.00041683333333333335" iyz="0.0" izz="3.3333333333333335e-07"/>
    </inertial>
  </link>
  <joint name="front_lower_top_left_joint" type="continuous">
    <parent link="front_lower_top_link"/>
    <child link="front_lower_left_link"/>
    <origin rpy="0 0 0" xyz="0 0.03 0"/>
    <axis xyz="1 0 0"/>
  </joint>
  <link name="front_lower_left_link">
    <collision>
      <origin rpy="0 0 0" xyz="0 0 -0.25"/>
      <geometry>
        <box size="0.01 0.01 0.5"/>
      </geometry>
    </collision>
    <visual>
      <origin rpy="0 0 0" xyz="0 0 -0.25"/>
      <geometry>
        <box size="0.01 0.01 0.5"/>
      </geometry>
      <material name="grey">
        <color rgba="0.2 0.2 0.2 1.0"/>
      </material>
    </visual>
    <inertial>
      <origin rpy="0 0 0" xyz="0 0 -0.25"/>
      <mass value="0.02"/>
      <inertia ixx="0.00041683333333333335" ixy="0.0" ixz="0.0" iyy="0.00041683333333333335" iyz="0.0" izz="3.3333333333333335e-07"/>
    </inertial>
  </link>
  <joint name="front_lower_right_bottom_joint" type="continuous">
    <parent link="front_lower_right_link"/>
    <child link="front_lower_bottom_link"/>
    <origin rpy="0 0 0" xyz="0 0 -0.5"/>
    <axis xyz="1 0 0"/>
  </joint>
  <link name="front_lower_bottom_link">
    <collision>
      <origin rpy="0 0 0" xyz="0 0.03 0"/>
      <geometry>
        <box size="0.01 0.06 0.01"/>
      </geometry>
    </collision>
    <visual>
      <origin rpy="0 0 0" xyz="0 0.03 0"/>
      <geometry>
        <box size="0.01 0.06 0.01"/>
      </geometry>
      <material name="grey">
        <color rgba="0.2 0.2 0.2 1.0"/>
      </material>
    </visual>
    <inertial>
      <origin rpy="0 0 0" xyz="0 0.03 0"/>
      <mass value="0.02"/>
      <inertia ixx="6.166666666666666e-06" ixy="0.0" ixz="0.0" iyy="6.166666666666666e-06" iyz="0.0" izz="3.3333333333333335e-07"/>
    </inertial>
  </link>
  <joint name="front_lower_bottom_end_joint" type="continuous">
    <parent link="front_lower_bottom_link"/>
    <child link="front_lower_end_link"/>
    <origin rpy="0 -0.5235987755982988 0" xyz="0 0.03 0"/>
    <axis xyz="0 1 0"/>
  </joint>
  <link name="front_lower_end_link">
    <collision>
      <origin rpy="0 0 0" xyz="-0.015 0 0"/>
      <geometry>
        <box size="0.03 0.01 0.01"/>
      </geometry>
    </collision>
    <visual>
      <origin rpy="0 0 0" xyz="-0.015 0 0"/>
      <geometry>
        <box size="0.03 0.01 0.01"/>
      </geometry>
      <material name="black">
        <color rgba="0.0 0.0 0.0 1.0"/>
      </material>
    </visual>
    <inertial>
      <origin rpy="0 0 0" xyz="-0.015 0 0"/>
      <mass value="0.02"/>
      <inertia ixx="3.3333333333333335e-07" ixy="0.0" ixz="0.0" iyy="1.6666666666666669e-06" iyz="0.0" izz="1.6666666666666669e-06"/>
    </inertial>
  </link>
  <joint name="front_lower_bottom_virtual_joint" type="continuous">
    <parent link="front_lower_bottom_link"/>
    <child link="front_lower_bottom_virtual_link"/>
    <origin rpy="0 0 0" xyz="0 0.06 0"/>
    <axis xyz="1 0 0"/>
  </joint>
  <link name="front_lower_bottom_virtual_link">
    <inertial>
      <origin rpy="0 0 0" xyz="0 0 0"/>
      <mass value="0.01"/>
      <inertia ixx="0.001" ixy="0.0" ixz="0.0" iyy="0.001" iyz="0.0" izz="0.001"/>
    </inertial>
  </link>
  <joint name="front_lower_left_virtual_joint" type="fixed">
    <parent link="front_lower_left_link"/>
    <child link="front_lower_left_virtual_link"/>
    <origin rpy="0 0 0" xyz="0 0 -0.5"/>
  </joint>
  <link name="front_lower_left_virtual_link">
    <inertial>
      <origin rpy="0 0 0" xyz="0 0 0"/>
      <mass value="0.01"/>
      <inertia ixx="0.001" ixy="0.0" ixz="0.0" iyy="0.001" iyz="0.0" izz="0.001"/>
    </inertial>
  </link>
  <gazebo>
    <joint name="front_lower_left_bottom_joint" type="fixed">
      <parent>front_lower_left_virtual_link</parent>
      <child>front_lower_bottom_virtual_link</child>
      <pose> 0 0 0 0 0 0 </pose>
    </joint>
  </gazebo>
  <gazebo reference="front_upper_link">
    <material>Gazebo/Black</material>
    <selfCollide>false</selfCollide>
  </gazebo>
  <gazebo reference="front_lower_top_link">
    <material>Gazebo/Grey</material>
    <selfCollide>false</selfCollide>
  </gazebo>
  <gazebo reference="front_lower_right_link">
    <material>Gazebo/Grey</material>
    <selfCollide>false</selfCollide>
  </gazebo>
  <gazebo reference="front_lower_left_link">
    <material>Gazebo/Grey</material>
    <selfCollide>false</selfCollide>
  </gazebo>
  <gazebo reference="front_lower_bottom_link">
    <material>Gazebo/Grey</material>
    <selfCollide>false</selfCollide>
  </gazebo>
  <gazebo reference="front_lower_end_link">
    <material>Gazebo/Black</material>
    <selfCollide>false</selfCollide>
  </gazebo>
  <transmission name="front_upper_joint_trans">
    <type>transmission_interface/SimpleTransmission</type>
    <joint name="front_upper_joint">
      <hardwareInterface>hardware_interface/EffortJointInterface</hardwareInterface>
    </joint>
    <actuator name="front_upper_joint_motor">
      <hardwareInterface>hardware_interface/EffortJointInterface</hardwareInterface>
      <mechanicalReduction>1</mechanicalReduction>
    </actuator>
  </transmission>
  <transmission name="front_lower_top_rignt_joint_trans">
    <type>transmission_interface/SimpleTransmission</type>
    <joint name="front_lower_top_rignt_joint">
      <hardwareInterface>hardware_interface/EffortJointInterface</hardwareInterface>
    </joint>
    <actuator name="front_lower_top_rignt_joint_motor">
      <hardwareInterface>hardware_interface/EffortJointInterface</hardwareInterface>
      <mechanicalReduction>1</mechanicalReduction>
    </actuator>
  </transmission>
  <transmission name="front_lower_top_left_joint_trans">
    <type>transmission_interface/SimpleTransmission</type>
    <joint name="front_lower_top_left_joint">
      <hardwareInterface>hardware_interface/EffortJointInterface</hardwareInterface>
    </joint>
    <actuator name="front_lower_top_left_joint_motor">
      <hardwareInterface>hardware_interface/EffortJointInterface</hardwareInterface>
      <mechanicalReduction>1</mechanicalReduction>
    </actuator>
  </transmission>
  <transmission name="front_lower_right_bottom_joint_trans">
    <type>transmission_interface/SimpleTransmission</type>
    <joint name="front_lower_right_bottom_joint">
      <hardwareInterface>hardware_interface/EffortJointInterface</hardwareInterface>
    </joint>
    <actuator name="front_lower_right_bottom_joint_motor">
      <hardwareInterface>hardware_interface/EffortJointInterface</hardwareInterface>
      <mechanicalReduction>1</mechanicalReduction>
    </actuator>
  </transmission>
  <transmission name="front_lower_bottom_end_joint_trans">
    <type>transmission_interface/SimpleTransmission</type>
    <joint name="front_lower_bottom_end_joint">
      <hardwareInterface>hardware_interface/EffortJointInterface</hardwareInterface>
    </joint>
    <actuator name="front_lower_bottom_end_joint_motor">
      <hardwareInterface>hardware_interface/EffortJointInterface</hardwareInterface>
      <mechanicalReduction>1</mechanicalReduction>
    </actuator>
  </transmission>
  <transmission name="front_lower_bottom_virtual_joint_trans">
    <type>transmission_interface/SimpleTransmission</type>
    <joint name="front_lower_bottom_virtual_joint">
      <hardwareInterface>hardware_interface/EffortJointInterface</hardwareInterface>
    </joint>
    <actuator name="front_lower_bottom_virtual_joint_motor">
      <hardwareInterface>hardware_interface/EffortJointInterface</hardwareInterface>
      <mechanicalReduction>1</mechanicalReduction>
    </actuator>
  </transmission>
  <joint name="front_delta_arm_joint" type="revolute">
    <parent link="base_link"/>
    <child link="front_upper_link"/>
    <origin rpy="0 0 0" xyz="0.1 0 0"/>
    <axis xyz="0 1 0"/>
    <dynamics damping="0.7"/>
    <limit effort="6" lower="-1.0471975511965976" upper="1.0471975511965976" velocity="8"/>
  </joint>
  <link name="right_upper_link">
    <collision>
      <origin rpy="0 0 0" xyz="0.1 0 0"/>
      <geometry>
        <box size="0.2 0.04 0.04"/>
      </geometry>
    </collision>
    <visual>
      <origin rpy="0 0 0" xyz="0.1 0 0"/>
      <geometry>
        <box size="0.2 0.04 0.04"/>
      </geometry>
      <material name="black">
        <color rgba="0.0 0.0 0.0 1.0"/>
      </material>
    </visual>
    <inertial>
      <origin rpy="0 0 0" xyz="0 0 0.1"/>
      <mass value="0.02"/>
      <inertia ixx="5.333333333333334e-06" ixy="0.0" ixz="0.0" iyy="6.933333333333334e-05" iyz="0.0" izz="6.933333333333334e-05"/>
    </inertial>
  </link>
  <joint name="right_upper_joint" type="continuous">
    <parent link="right_upper_link"/>
    <child link="right_lower_top_link"/>
    <origin rpy="0 0.5235987755982988 0" xyz="0.2 0 0"/>
    <axis xyz="0 1 0"/>
  </joint>
  <link name="right_lower_top_link">
    <collision>
      <origin rpy="0 0 0" xyz="0 0 0"/>
      <geometry>
        <box size="0.01 0.06 0.01"/>
      </geometry>
    </collision>
    <visual>
      <origin rpy="0 0 0" xyz="0 0 0"/>
      <geometry>
        <box size="0.01 0.06 0.01"/>
      </geometry>
      <material name="grey">
        <color rgba="0.2 0.2 0.2 1.0"/>
      </material>
    </visual>
    <inertial>
      <origin rpy="0 0 0" xyz="0 0 0"/>
      <mass value="0.02"/>
      <inertia ixx="6.166666666666666e-06" ixy="0.0" ixz="0.0" iyy="3.3333333333333335e-07" iyz="0.0" izz="6.166666666666666e-06"/>
    </inertial>
  </link>
  <joint name="right_lower_top_rignt_joint" type="continuous">
    <parent link="right_lower_top_link"/>
    <child link="right_lower_right_link"/>
    <origin rpy="0 0 0" xyz="0 -0.03 0"/>
    <axis xyz="1 0 0"/>
  </joint>
  <link name="right_lower_right_link">
    <collision>
      <origin rpy="0 0 0" xyz="0 0 -0.25"/>
      <geometry>
        <box size="0.01 0.01 0.5"/>
      </geometry>
    </collision>
    <visual>
      <origin rpy="0 0 0" xyz="0 0 -0.25"/>
      <geometry>
        <box size="0.01 0.01 0.5"/>
      </geometry>
      <material name="grey">
        <color rgba="0.2 0.2 0.2 1.0"/>
      </material>
    </visual>
    <inertial>
      <origin rpy="0 0 0" xyz="0 0 -0.25"/>
      <mass value="0.02"/>
      <inertia ixx="0.00041683333333333335" ixy="0.0" ixz="0.0" iyy="0.00041683333333333335" iyz="0.0" izz="3.3333333333333335e-07"/>
    </inertial>
  </link>
  <joint name="right_lower_top_left_joint" type="continuous">
    <parent link="right_lower_top_link"/>
    <child link="right_lower_left_link"/>
    <origin rpy="0 0 0" xyz="0 0.03 0"/>
    <axis xyz="1 0 0"/>
  </joint>
  <link name="right_lower_left_link">
    <collision>
      <origin rpy="0 0 0" xyz="0 0 -0.25"/>
      <geometry>
        <box size="0.01 0.01 0.5"/>
      </geometry>
    </collision>
    <visual>
      <origin rpy="0 0 0" xyz="0 0 -0.25"/>
      <geometry>
        <box size="0.01 0.01 0.5"/>
      </geometry>
      <material name="grey">
        <color rgba="0.2 0.2 0.2 1.0"/>
      </material>
    </visual>
    <inertial>
      <origin rpy="0 0 0" xyz="0 0 -0.25"/>
      <mass value="0.02"/>
      <inertia ixx="0.00041683333333333335" ixy="0.0" ixz="0.0" iyy="0.00041683333333333335" iyz="0.0" izz="3.3333333333333335e-07"/>
    </inertial>
  </link>
  <joint name="right_lower_right_bottom_joint" type="continuous">
    <parent link="right_lower_right_link"/>
    <child link="right_lower_bottom_link"/>
    <origin rpy="0 0 0" xyz="0 0 -0.5"/>
    <axis xyz="1 0 0"/>
  </joint>
  <link name="right_lower_bottom_link">
    <collision>
      <origin rpy="0 0 0" xyz="0 0.03 0"/>
      <geometry>
        <box size="0.01 0.06 0.01"/>
      </geometry>
    </collision>
    <visual>
      <origin rpy="0 0 0" xyz="0 0.03 0"/>
      <geometry>
        <box size="0.01 0.06 0.01"/>
      </geometry>
      <material name="grey">
        <color rgba="0.2 0.2 0.2 1.0"/>
      </material>
    </visual>
    <inertial>
      <origin rpy="0 0 0" xyz="0 0.03 0"/>
      <mass value="0.02"/>
      <inertia ixx="6.166666666666666e-06" ixy="0.0" ixz="0.0" iyy="6.166666666666666e-06" iyz="0.0" izz="3.3333333333333335e-07"/>
    </inertial>
  </link>
  <joint name="right_lower_bottom_end_joint" type="continuous">
    <parent link="right_lower_bottom_link"/>
    <child link="right_lower_end_link"/>
    <origin rpy="0 -0.5235987755982988 0" xyz="0 0.03 0"/>
    <axis xyz="0 1 0"/>
  </joint>
  <link name="right_lower_end_link">
    <collision>
      <origin rpy="0 0 0" xyz="-0.015 0 0"/>
      <geometry>
        <box size="0.03 0.01 0.01"/>
      </geometry>
    </collision>
    <visual>
      <origin rpy="0 0 0" xyz="-0.015 0 0"/>
      <geometry>
        <box size="0.03 0.01 0.01"/>
      </geometry>
      <material name="black">
        <color rgba="0.0 0.0 0.0 1.0"/>
      </material>
    </visual>
    <inertial>
      <origin rpy="0 0 0" xyz="-0.015 0 0"/>
      <mass value="0.02"/>
      <inertia ixx="3.3333333333333335e-07" ixy="0.0" ixz="0.0" iyy="1.6666666666666669e-06" iyz="0.0" izz="1.6666666666666669e-06"/>
    </inertial>
  </link>
  <joint name="right_lower_bottom_virtual_joint" type="continuous">
    <parent link="right_lower_bottom_link"/>
    <child link="right_lower_bottom_virtual_link"/>
    <origin rpy="0 0 0" xyz="0 0.06 0"/>
    <axis xyz="1 0 0"/>
  </joint>
  <link name="right_lower_bottom_virtual_link">
    <inertial>
      <origin rpy="0 0 0" xyz="0 0 0"/>
      <mass value="0.01"/>
      <inertia ixx="0.001" ixy="0.0" ixz="0.0" iyy="0.001" iyz="0.0" izz="0.001"/>
    </inertial>
  </link>
  <joint name="right_lower_left_virtual_joint" type="fixed">
    <parent link="right_lower_left_link"/>
    <child link="right_lower_left_virtual_link"/>
    <origin rpy="0 0 0" xyz="0 0 -0.5"/>
  </joint>
  <link name="right_lower_left_virtual_link">
    <inertial>
      <origin rpy="0 0 0" xyz="0 0 0"/>
      <mass value="0.01"/>
      <inertia ixx="0.001" ixy="0.0" ixz="0.0" iyy="0.001" iyz="0.0" izz="0.001"/>
    </inertial>
  </link>
  <gazebo>
    <joint name="right_lower_left_bottom_joint" type="fixed">
      <parent>right_lower_left_virtual_link</parent>
      <child>right_lower_bottom_virtual_link</child>
      <pose> 0 0 0 0 0 0 </pose>
    </joint>
  </gazebo>
  <gazebo reference="right_upper_link">
    <material>Gazebo/Black</material>
    <selfCollide>false</selfCollide>
  </gazebo>
  <gazebo reference="right_lower_top_link">
    <material>Gazebo/Grey</material>
    <selfCollide>false</selfCollide>
  </gazebo>
  <gazebo reference="right_lower_right_link">
    <material>Gazebo/Grey</material>
    <selfCollide>false</selfCollide>
  </gazebo>
  <gazebo reference="right_lower_left_link">
    <material>Gazebo/Grey</material>
    <selfCollide>false</selfCollide>
  </gazebo>
  <gazebo reference="right_lower_bottom_link">
    <material>Gazebo/Grey</material>
    <selfCollide>false</selfCollide>
  </gazebo>
  <gazebo reference="right_lower_end_link">
    <material>Gazebo/Black</material>
    <selfCollide>false</selfCollide>
  </gazebo>
  <transmission name="right_upper_joint_trans">
    <type>transmission_interface/SimpleTransmission</type>
    <joint name="right_upper_joint">
      <hardwareInterface>hardware_interface/EffortJointInterface</hardwareInterface>
    </joint>
    <actuator name="right_upper_joint_motor">
      <hardwareInterface>hardware_interface/EffortJointInterface</hardwareInterface>
      <mechanicalReduction>1</mechanicalReduction>
    </actuator>
  </transmission>
  <transmission name="right_lower_top_rignt_joint_trans">
    <type>transmission_interface/SimpleTransmission</type>
    <joint name="right_lower_top_rignt_joint">
      <hardwareInterface>hardware_interface/EffortJointInterface</hardwareInterface>
    </joint>
    <actuator name="right_lower_top_rignt_joint_motor">
      <hardwareInterface>hardware_interface/EffortJointInterface</hardwareInterface>
      <mechanicalReduction>1</mechanicalReduction>
    </actuator>
  </transmission>
  <transmission name="right_lower_top_left_joint_trans">
    <type>transmission_interface/SimpleTransmission</type>
    <joint name="right_lower_top_left_joint">
      <hardwareInterface>hardware_interface/EffortJointInterface</hardwareInterface>
    </joint>
    <actuator name="right_lower_top_left_joint_motor">
      <hardwareInterface>hardware_interface/EffortJointInterface</hardwareInterface>
      <mechanicalReduction>1</mechanicalReduction>
    </actuator>
  </transmission>
  <transmission name="right_lower_right_bottom_joint_trans">
    <type>transmission_interface/SimpleTransmission</type>
    <joint name="right_lower_right_bottom_joint">
      <hardwareInterface>hardware_interface/EffortJointInterface</hardwareInterface>
    </joint>
    <actuator name="right_lower_right_bottom_joint_motor">
      <hardwareInterface>hardware_interface/EffortJointInterface</hardwareInterface>
      <mechanicalReduction>1</mechanicalReduction>
    </actuator>
  </transmission>
  <transmission name="right_lower_bottom_end_joint_trans">
    <type>transmission_interface/SimpleTransmission</type>
    <joint name="right_lower_bottom_end_joint">
      <hardwareInterface>hardware_interface/EffortJointInterface</hardwareInterface>
    </joint>
    <actuator name="right_lower_bottom_end_joint_motor">
      <hardwareInterface>hardware_interface/EffortJointInterface</hardwareInterface>
      <mechanicalReduction>1</mechanicalReduction>
    </actuator>
  </transmission>
  <transmission name="right_lower_bottom_virtual_joint_trans">
    <type>transmission_interface/SimpleTransmission</type>
    <joint name="right_lower_bottom_virtual_joint">
      <hardwareInterface>hardware_interface/EffortJointInterface</hardwareInterface>
    </joint>
    <actuator name="right_lower_bottom_virtual_joint_motor">
      <hardwareInterface>hardware_interface/EffortJointInterface</hardwareInterface>
      <mechanicalReduction>1</mechanicalReduction>
    </actuator>
  </transmission>
  <joint name="right_delta_arm_joint" type="revolute">
    <parent link="base_link"/>
    <child link="right_upper_link"/>
    <origin rpy="0 0 -2.0943951023931953" xyz="-0.05 -0.0866 0"/>
    <axis xyz="0 1 0"/>
    <dynamics damping="0.7"/>
    <limit effort="6" lower="-1.0471975511965976" upper="1.0471975511965976" velocity="8"/>
  </joint>
  <link name="left_upper_link">
    <collision>
      <origin rpy="0 0 0" xyz="0.1 0 0"/>
      <geometry>
        <box size="0.2 0.04 0.04"/>
      </geometry>
    </collision>
    <visual>
      <origin rpy="0 0 0" xyz="0.1 0 0"/>
      <geometry>
        <box size="0.2 0.04 0.04"/>
      </geometry>
      <material name="black">
        <color rgba="0.0 0.0 0.0 1.0"/>
      </material>
    </visual>
    <inertial>
      <origin rpy="0 0 0" xyz="0 0 0.1"/>
      <mass value="0.02"/>
      <inertia ixx="5.333333333333334e-06" ixy="0.0" ixz="0.0" iyy="6.933333333333334e-05" iyz="0.0" izz="6.933333333333334e-05"/>
    </inertial>
  </link>
  <joint name="left_upper_joint" type="continuous">
    <parent link="left_upper_link"/>
    <child link="left_lower_top_link"/>
    <origin rpy="0 0.5235987755982988 0" xyz="0.2 0 0"/>
    <axis xyz="0 1 0"/>
  </joint>
  <link name="left_lower_top_link">
    <collision>
      <origin rpy="0 0 0" xyz="0 0 0"/>
      <geometry>
        <box size="0.01 0.06 0.01"/>
      </geometry>
    </collision>
    <visual>
      <origin rpy="0 0 0" xyz="0 0 0"/>
      <geometry>
        <box size="0.01 0.06 0.01"/>
      </geometry>
      <material name="grey">
        <color rgba="0.2 0.2 0.2 1.0"/>
      </material>
    </visual>
    <inertial>
      <origin rpy="0 0 0" xyz="0 0 0"/>
      <mass value="0.02"/>
      <inertia ixx="6.166666666666666e-06" ixy="0.0" ixz="0.0" iyy="3.3333333333333335e-07" iyz="0.0" izz="6.166666666666666e-06"/>
    </inertial>
  </link>
  <joint name="left_lower_top_rignt_joint" type="continuous">
    <parent link="left_lower_top_link"/>
    <child link="left_lower_right_link"/>
    <origin rpy="0 0 0" xyz="0 -0.03 0"/>
    <axis xyz="1 0 0"/>
  </joint>
  <link name="left_lower_right_link">
    <collision>
      <origin rpy="0 0 0" xyz="0 0 -0.25"/>
      <geometry>
        <box size="0.01 0.01 0.5"/>
      </geometry>
    </collision>
    <visual>
      <origin rpy="0 0 0" xyz="0 0 -0.25"/>
      <geometry>
        <box size="0.01 0.01 0.5"/>
      </geometry>
      <material name="grey">
        <color rgba="0.2 0.2 0.2 1.0"/>
      </material>
    </visual>
    <inertial>
      <origin rpy="0 0 0" xyz="0 0 -0.25"/>
      <mass value="0.02"/>
      <inertia ixx="0.00041683333333333335" ixy="0.0" ixz="0.0" iyy="0.00041683333333333335" iyz="0.0" izz="3.3333333333333335e-07"/>
    </inertial>
  </link>
  <joint name="left_lower_top_left_joint" type="continuous">
    <parent link="left_lower_top_link"/>
    <child link="left_lower_left_link"/>
    <origin rpy="0 0 0" xyz="0 0.03 0"/>
    <axis xyz="1 0 0"/>
  </joint>
  <link name="left_lower_left_link">
    <collision>
      <origin rpy="0 0 0" xyz="0 0 -0.25"/>
      <geometry>
        <box size="0.01 0.01 0.5"/>
      </geometry>
    </collision>
    <visual>
      <origin rpy="0 0 0" xyz="0 0 -0.25"/>
      <geometry>
        <box size="0.01 0.01 0.5"/>
      </geometry>
      <material name="grey">
        <color rgba="0.2 0.2 0.2 1.0"/>
      </material>
    </visual>
    <inertial>
      <origin rpy="0 0 0" xyz="0 0 -0.25"/>
      <mass value="0.02"/>
      <inertia ixx="0.00041683333333333335" ixy="0.0" ixz="0.0" iyy="0.00041683333333333335" iyz="0.0" izz="3.3333333333333335e-07"/>
    </inertial>
  </link>
  <joint name="left_lower_right_bottom_joint" type="continuous">
    <parent link="left_lower_right_link"/>
    <child link="left_lower_bottom_link"/>
    <origin rpy="0 0 0" xyz="0 0 -0.5"/>
    <axis xyz="1 0 0"/>
  </joint>
  <link name="left_lower_bottom_link">
    <collision>
      <origin rpy="0 0 0" xyz="0 0.03 0"/>
      <geometry>
        <box size="0.01 0.06 0.01"/>
      </geometry>
    </collision>
    <visual>
      <origin rpy="0 0 0" xyz="0 0.03 0"/>
      <geometry>
        <box size="0.01 0.06 0.01"/>
      </geometry>
      <material name="grey">
        <color rgba="0.2 0.2 0.2 1.0"/>
      </material>
    </visual>
    <inertial>
      <origin rpy="0 0 0" xyz="0 0.03 0"/>
      <mass value="0.02"/>
      <inertia ixx="6.166666666666666e-06" ixy="0.0" ixz="0.0" iyy="6.166666666666666e-06" iyz="0.0" izz="3.3333333333333335e-07"/>
    </inertial>
  </link>
  <joint name="left_lower_bottom_end_joint" type="continuous">
    <parent link="left_lower_bottom_link"/>
    <child link="left_lower_end_link"/>
    <origin rpy="0 -0.5235987755982988 0" xyz="0 0.03 0"/>
    <axis xyz="0 1 0"/>
  </joint>
  <link name="left_lower_end_link">
    <collision>
      <origin rpy="0 0 0" xyz="-0.015 0 0"/>
      <geometry>
        <box size="0.03 0.01 0.01"/>
      </geometry>
    </collision>
    <visual>
      <origin rpy="0 0 0" xyz="-0.015 0 0"/>
      <geometry>
        <box size="0.03 0.01 0.01"/>
      </geometry>
      <material name="black">
        <color rgba="0.0 0.0 0.0 1.0"/>
      </material>
    </visual>
    <inertial>
      <origin rpy="0 0 0" xyz="-0.015 0 0"/>
      <mass value="0.02"/>
      <inertia ixx="3.3333333333333335e-07" ixy="0.0" ixz="0.0" iyy="1.6666666666666669e-06" iyz="0.0" izz="1.6666666666666669e-06"/>
    </inertial>
  </link>
  <joint name="left_lower_bottom_virtual_joint" type="continuous">
    <parent link="left_lower_bottom_link"/>
    <child link="left_lower_bottom_virtual_link"/>
    <origin rpy="0 0 0" xyz="0 0.06 0"/>
    <axis xyz="1 0 0"/>
  </joint>
  <link name="left_lower_bottom_virtual_link">
    <inertial>
      <origin rpy="0 0 0" xyz="0 0 0"/>
      <mass value="0.01"/>
      <inertia ixx="0.001" ixy="0.0" ixz="0.0" iyy="0.001" iyz="0.0" izz="0.001"/>
    </inertial>
  </link>
  <joint name="left_lower_left_virtual_joint" type="fixed">
    <parent link="left_lower_left_link"/>
    <child link="left_lower_left_virtual_link"/>
    <origin rpy="0 0 0" xyz="0 0 -0.5"/>
  </joint>
  <link name="left_lower_left_virtual_link">
    <inertial>
      <origin rpy="0 0 0" xyz="0 0 0"/>
      <mass value="0.01"/>
      <inertia ixx="0.001" ixy="0.0" ixz="0.0" iyy="0.001" iyz="0.0" izz="0.001"/>
    </inertial>
  </link>
  <gazebo>
    <joint name="left_lower_left_bottom_joint" type="fixed">
      <parent>left_lower_left_virtual_link</parent>
      <child>left_lower_bottom_virtual_link</child>
      <pose> 0 0 0 0 0 0 </pose>
    </joint>
  </gazebo>
  <gazebo reference="left_upper_link">
    <material>Gazebo/Black</material>
    <selfCollide>false</selfCollide>
  </gazebo>
  <gazebo reference="left_lower_top_link">
    <material>Gazebo/Grey</material>
    <selfCollide>false</selfCollide>
  </gazebo>
  <gazebo reference="left_lower_right_link">
    <material>Gazebo/Grey</material>
    <selfCollide>false</selfCollide>
  </gazebo>
  <gazebo reference="left_lower_left_link">
    <material>Gazebo/Grey</material>
    <selfCollide>false</selfCollide>
  </gazebo>
  <gazebo reference="left_lower_bottom_link">
    <material>Gazebo/Grey</material>
    <selfCollide>false</selfCollide>
  </gazebo>
  <gazebo reference="left_lower_end_link">
    <material>Gazebo/Black</material>
    <selfCollide>false</selfCollide>
  </gazebo>
  <transmission name="left_upper_joint_trans">
    <type>transmission_interface/SimpleTransmission</type>
    <joint name="left_upper_joint">
      <hardwareInterface>hardware_interface/EffortJointInterface</hardwareInterface>
    </joint>
    <actuator name="left_upper_joint_motor">
      <hardwareInterface>hardware_interface/EffortJointInterface</hardwareInterface>
      <mechanicalReduction>1</mechanicalReduction>
    </actuator>
  </transmission>
  <transmission name="left_lower_top_rignt_joint_trans">
    <type>transmission_interface/SimpleTransmission</type>
    <joint name="left_lower_top_rignt_joint">
      <hardwareInterface>hardware_interface/EffortJointInterface</hardwareInterface>
    </joint>
    <actuator name="left_lower_top_rignt_joint_motor">
      <hardwareInterface>hardware_interface/EffortJointInterface</hardwareInterface>
      <mechanicalReduction>1</mechanicalReduction>
    </actuator>
  </transmission>
  <transmission name="left_lower_top_left_joint_trans">
    <type>transmission_interface/SimpleTransmission</type>
    <joint name="left_lower_top_left_joint">
      <hardwareInterface>hardware_interface/EffortJointInterface</hardwareInterface>
    </joint>
    <actuator name="left_lower_top_left_joint_motor">
      <hardwareInterface>hardware_interface/EffortJointInterface</hardwareInterface>
      <mechanicalReduction>1</mechanicalReduction>
    </actuator>
  </transmission>
  <transmission name="left_lower_right_bottom_joint_trans">
    <type>transmission_interface/SimpleTransmission</type>
    <joint name="left_lower_right_bottom_joint">
      <hardwareInterface>hardware_interface/EffortJointInterface</hardwareInterface>
    </joint>
    <actuator name="left_lower_right_bottom_joint_motor">
      <hardwareInterface>hardware_interface/EffortJointInterface</hardwareInterface>
      <mechanicalReduction>1</mechanicalReduction>
    </actuator>
  </transmission>
  <transmission name="left_lower_bottom_end_joint_trans">
    <type>transmission_interface/SimpleTransmission</type>
    <joint name="left_lower_bottom_end_joint">
      <hardwareInterface>hardware_interface/EffortJointInterface</hardwareInterface>
    </joint>
    <actuator name="left_lower_bottom_end_joint_motor">
      <hardwareInterface>hardware_interface/EffortJointInterface</hardwareInterface>
      <mechanicalReduction>1</mechanicalReduction>
    </actuator>
  </transmission>
  <transmission name="left_lower_bottom_virtual_joint_trans">
    <type>transmission_interface/SimpleTransmission</type>
    <joint name="left_lower_bottom_virtual_joint">
      <hardwareInterface>hardware_interface/EffortJointInterface</hardwareInterface>
    </joint>
    <actuator name="left_lower_bottom_virtual_joint_motor">
      <hardwareInterface>hardware_interface/EffortJointInterface</hardwareInterface>
      <mechanicalReduction>1</mechanicalReduction>
    </actuator>
  </transmission>
  <joint name="left_delta_arm_joint" type="revolute">
    <parent link="base_link"/>
    <child link="left_upper_link"/>
    <origin rpy="0 0 2.0943951023931953" xyz="-0.05 0.0866 0"/>
    <axis xyz="0 1 0"/>
    <dynamics damping="0.7"/>
    <limit effort="6" lower="-1.0471975511965976" upper="1.0471975511965976" velocity="8"/>
  </joint>
  <link name="end_link">
    <collision>
      <origin rpy="0 0 0" xyz="0 0 0"/>
      <geometry>
        <cylinder length="0.0125" radius="0.025"/>
      </geometry>
    </collision>
    <visual>
      <origin rpy="0 0 0" xyz="0 0 0"/>
      <geometry>
        <cylinder length="0.0125" radius="0.025"/>
      </geometry>
      <material name="orange">
        <color rgba="1.0 0.4235294117647059 0.0392156862745098 1.0"/>
      </material>
    </visual>
    <inertial>
      <origin rpy="0 0 0" xyz="0 0 0"/>
      <mass value="0.1"/>
      <inertia ixx="0.001" ixy="0.0" ixz="0.0" iyy="0.001" iyz="0.0" izz="0.001"/>
    </inertial>
  </link>
  <joint name="front_end_joint" type="fixed">
    <parent link="front_lower_end_link"/>
    <child link="end_link"/>
    <origin rpy="0 0 0" xyz="-0.05 0 0"/>
  </joint>
  <link name="right_end_virtual_link">
    <inertial>
      <origin rpy="0 0 0" xyz="0 0 0"/>
      <mass value="0.001"/>
      <inertia ixx="0.0001" ixy="0.0" ixz="0.0" iyy="0.0001" iyz="0.0" izz="0.0001"/>
    </inertial>
  </link>
  <joint name="right_end_virtual_joint" type="fixed">
    <parent link="end_link"/>
    <child link="right_end_virtual_link"/>
    <origin rpy="0 0 -2.0943951023931953" xyz="-0.025 -0.0433 0"/>
  </joint>
  <link name="left_end_virtual_link">
    <inertial>
      <origin rpy="0 0 0" xyz="0 0 0"/>
      <mass value="0.001"/>
      <inertia ixx="0.0001" ixy="0.0" ixz="0.0" iyy="0.0001" iyz="0.0" izz="0.0001"/>
    </inertial>
  </link>
  <joint name="left_end_virtual_joint" type="fixed">
    <parent link="end_link"/>
    <child link="left_end_virtual_link"/>
    <origin rpy="0 0 2.0943951023931953" xyz="-0.025 0.0433 0"/>
  </joint>
  <gazebo>
    <joint name="right_end_joint" type="fixed">
      <parent>right_lower_end_link</parent>
      <child>right_end_virtual_link</child>
      <pose> 0 0 0 0 0 0 </pose>
    </joint>
    <joint name="left_end_joint" type="fixed">
      <parent>left_lower_end_link</parent>
      <child>left_end_virtual_link</child>
      <pose> 0 0 0 0 0 0 </pose>
    </joint>
  </gazebo>
</robot>
