<?xml version="1.0" ?>
<!-- =================================================================================== -->
<!-- |    This document was autogenerated by xacro from delta.urdf.xacro               | -->
<!-- |    EDITING THIS FILE BY HAND IS NOT RECOMMENDED                                 | -->
<!-- =================================================================================== -->
<robot name="delta">
  <!-- Base of the robot -->
  <link name="world"/>
  <link name="base_link">
    <visual>
      <origin xyz="0.0 0.0 0.00635"/>
      <geometry>
        <cylinder length="0.0127" radius="0.111"/>
      </geometry>
      <material name="green">
        <color rgba="0.2 1 0.2 1"/>
      </material>
    </visual>
    <collision>
      <origin xyz="0.0 0.0 0.00635"/>
      <geometry>
        <cylinder length="0.0127" radius="0.111"/>
      </geometry>
    </collision>
    <inertial>
      <origin xyz="0.0 0.0 0.00635"/>
      <mass value="12"/>
      <inertia ixx="0.037124290000000004" ixy="0.0" ixz="0.0" iyy="0.037124290000000004" iyz="0.0" izz="0.073926"/>
    </inertial>
  </link>
  <joint name="world_base_joint" type="fixed">
    <origin rpy="0.0 0.0 0.0" xyz="1 0.0 0.0"/>
    <parent link="world"/>
    <child link="base_link"/>
  </joint>
  <!-- First Arm -->
  <link name="arm_1_link">
    <visual>
      <origin rpy="0.0 0.0 0.0" xyz="-0.09 0.0 0.0"/>
      <geometry>
        <box size="0.185 0.00635 0.043"/>
      </geometry>
      <material name="green"/>
    </visual>
    <collision>
      <origin rpy="0.0 0.0 0.0" xyz="-0.09 0.0 0.0"/>
      <geometry>
        <box size="0.185 0.00635 0.043"/>
      </geometry>
    </collision>
    <inertial>
      <origin rpy="0.0 0.0 0.0" xyz="-0.09 0.0 0.0"/>
      <mass value="6"/>
      <inertia ixx="0.0009446612499999998" ixy="0.0" ixz="0.0" iyy="0.018036999999999997" iyz="0.0" izz="0.01713266125"/>
    </inertial>
  </link>
  <joint name="base_arm_1_joint" type="revolute">
    <origin rpy="0.0 0.0 0.0" xyz="-0.115 0.0 0.0254"/>
    <parent link="base_link"/>
    <child link="arm_1_link"/>
    <axis xyz="0.0 1.0 0.0"/>
    <limit effort="100.0" lower="-1.5707963267948966" upper="1.5707963267948966" velocity="100.0"/>
    <dynamics damping="4" friction="4"/>
  </joint>
  <!-- Second Arm -->
  <link name="arm_2_link">
    <visual>
      <origin rpy="0.0 0.0 0.0" xyz="-0.09 0.0 0.0"/>
      <geometry>
        <box size="0.185 0.00635 0.043"/>
      </geometry>
      <material name="green"/>
    </visual>
    <collision>
      <origin rpy="0.0 0.0 0.0" xyz="-0.09 0.0 0.0"/>
      <geometry>
        <box size="0.185 0.00635 0.043"/>
      </geometry>
    </collision>
    <inertial>
      <origin rpy="0.0 0.0 0.0" xyz="-0.09 0.0 0.0"/>
      <mass value="6"/>
      <inertia ixx="0.0009446612499999998" ixy="0.0" ixz="0.0" iyy="0.018036999999999997" iyz="0.0" izz="0.01713266125"/>
    </inertial>
  </link>
  <joint name="base_arm_2_joint" type="revolute">
    <origin rpy="0.0 0.0 -2.0943951023931953" xyz="0.055 0.096 0.0254"/>
    <parent link="base_link"/>
    <child link="arm_2_link"/>
    <axis xyz="0.0 1.0 0.0"/>
    <limit effort="100.0" lower="-1.5707963267948966" upper="1.5707963267948966" velocity="100.0"/>
    <dynamics damping="4" friction="4"/>
  </joint>
  <!-- Third Arm -->
  <link name="arm_3_link">
    <visual>
      <origin rpy="0.0 0.0 0.0" xyz="-0.09 0.0 0.0"/>
      <geometry>
        <box size="0.185 0.00635 0.043"/>
      </geometry>
      <material name="green"/>
    </visual>
    <collision>
      <origin rpy="0.0 0.0 0.0" xyz="-0.09 0.0 0.0"/>
      <geometry>
        <box size="0.185 0.00635 0.043"/>
      </geometry>
    </collision>
    <inertial>
      <origin rpy="0.0 0.0 0.0" xyz="-0.09 0.0 0.0"/>
      <mass value="6"/>
      <inertia ixx="0.0009446612499999998" ixy="0.0" ixz="0.0" iyy="0.018036999999999997" iyz="0.0" izz="0.01713266125"/>
    </inertial>
  </link>
  <joint name="base_arm_3_joint" type="revolute">
    <origin rpy="0.0 0.0 2.0943951023931953" xyz="0.055 -0.096 0.0254"/>
    <parent link="base_link"/>
    <child link="arm_3_link"/>
    <axis xyz="0.0 1.0 0.0"/>
    <limit effort="100.0" lower="-1.5707963267948966" upper="1.5707963267948966" velocity="100.0"/>
    <dynamics damping="4" friction="4"/>
  </joint>
  <!-- Forearm 1 -->
  <link name="forearm_1_link">
    <visual>
      <origin rpy="0.0 0.0 0.0" xyz="0.0 0.0 0.175"/>
      <geometry>
        <cylinder length="0.350" radius="0.00635"/>
      </geometry>
      <material name="green"/>
    </visual>
    <collision>
      <origin rpy="0.0 0.0 0.0" xyz="0.0 0.0 0.175"/>
      <geometry>
        <cylinder length="0.350" radius="0.00635"/>
      </geometry>
    </collision>
    <inertial>
      <origin xyz="0.0 0.0 0.0"/>
      <mass value="4"/>
      <inertia ixx="0.12251344083333332" ixy="0.0" ixz="0.0" iyy="0.12251344083333332" iyz="0.0" izz="0.24499999999999997"/>
    </inertial>
  </link>
  <!-- Spherical Joint 1 -->
  <link name="virtual_link_1_1">
    <inertial>
      <origin xyz="0.0 0.0 0.0"/>
      <mass value="0.1"/>
      <inertia ixx="1.6666666666666667e-06" ixy="0.0" ixz="0.0" iyy="1.6666666666666667e-06" iyz="0.0" izz="1.6666666666666667e-06"/>
    </inertial>
  </link>
  <link name="virtual_link_1_2">
    <inertial>
      <origin xyz="0.0 0.0 0.0"/>
      <mass value="0.1"/>
      <inertia ixx="1.6666666666666667e-06" ixy="0.0" ixz="0.0" iyy="1.6666666666666667e-06" iyz="0.0" izz="1.6666666666666667e-06"/>
    </inertial>
  </link>
  <joint name="arm_forearm_1_1_joint" type="revolute">
    <origin rpy="0.0 0.0 0.0" xyz="-0.190 0.0 0.0"/>
    <parent link="arm_1_link"/>
    <child link="virtual_link_1_1"/>
    <axis xyz="1.0 0.0 0.0"/>
    <limit effort="100.0" lower="-0.41887902047863906" upper="0.41887902047863906" velocity="100.0"/>
    <dynamics damping="0.0" friction="0.003"/>
  </joint>
  <joint name="arm_forearm_1_2_joint" type="revolute">
    <parent link="virtual_link_1_1"/>
    <child link="virtual_link_1_2"/>
    <axis xyz="0.0 1.0 0.0"/>
    <limit effort="100.0" lower="-3.141592653589793" upper="3.141592653589793" velocity="100.0"/>
    <dynamics damping="0.0" friction="0.003"/>
  </joint>
  <joint name="arm_forearm_1_3_joint" type="revolute">
    <parent link="virtual_link_1_2"/>
    <child link="forearm_1_link"/>
    <axis xyz="0.0 0.0 1.0"/>
    <limit effort="100.0" lower="-0.41887902047863906" upper="0.41887902047863906" velocity="100.0"/>
    <dynamics damping="0.0" friction="0.003"/>
  </joint>
  <!-- Forearm 2 -->
  <link name="forearm_2_link">
    <visual>
      <origin rpy="0.0 0.0 0.0" xyz="0.0 0.0 0.175"/>
      <geometry>
        <cylinder length="0.350" radius="0.00635"/>
      </geometry>
      <material name="green"/>
    </visual>
    <collision>
      <origin rpy="0.0 0.0 0.0" xyz="0.0 0.0 0.175"/>
      <geometry>
        <cylinder length="0.350" radius="0.00635"/>
      </geometry>
    </collision>
    <inertial>
      <origin xyz="0.0 0.0 0.0"/>
      <mass value="4"/>
      <inertia ixx="0.12251344083333332" ixy="0.0" ixz="0.0" iyy="0.12251344083333332" iyz="0.0" izz="0.24499999999999997"/>
    </inertial>
  </link>
  <!-- Spherical Joint 2 -->
  <link name="virtual_link_2_1">
    <inertial>
      <origin xyz="0.0 0.0 0.0"/>
      <mass value="0.1"/>
      <inertia ixx="1.6666666666666667e-06" ixy="0.0" ixz="0.0" iyy="1.6666666666666667e-06" iyz="0.0" izz="1.6666666666666667e-06"/>
    </inertial>
  </link>
  <link name="virtual_link_2_2">
    <inertial>
      <origin xyz="0.0 0.0 0.0"/>
      <mass value="0.1"/>
      <inertia ixx="1.6666666666666667e-06" ixy="0.0" ixz="0.0" iyy="1.6666666666666667e-06" iyz="0.0" izz="1.6666666666666667e-06"/>
    </inertial>
  </link>
  <joint name="arm_forearm_2_1_joint" type="revolute">
    <origin rpy="0.0 0.0 0.0" xyz="-0.190 0.0 0.0"/>
    <parent link="arm_2_link"/>
    <child link="virtual_link_2_1"/>
    <axis xyz="1.0 0.0 0.0"/>
    <limit effort="100.0" lower="-0.41887902047863906" upper="0.41887902047863906" velocity="100.0"/>
  </joint>
  <joint name="arm_forearm_2_2_joint" type="revolute">
    <parent link="virtual_link_2_1"/>
    <child link="virtual_link_2_2"/>
    <axis xyz="0.0 1.0 0.0"/>
    <limit effort="100.0" lower="-3.141592653589793" upper="3.141592653589793" velocity="100.0"/>
  </joint>
  <joint name="arm_forearm_2_3_joint" type="revolute">
    <parent link="virtual_link_2_2"/>
    <child link="forearm_2_link"/>
    <axis xyz="0.0 0.0 1.0"/>
    <limit effort="100.0" lower="-0.41887902047863906" upper="0.41887902047863906" velocity="100.0"/>
  </joint>
  <!-- Forearm 3 -->
  <link name="forearm_3_link">
    <visual>
      <origin rpy="0.0 0.0 0.0" xyz="0.0 0.0 0.175"/>
      <geometry>
        <cylinder length="0.350" radius="0.00635"/>
      </geometry>
      <material name="green"/>
    </visual>
    <collision>
      <origin rpy="0.0 0.0 0.0" xyz="0.0 0.0 0.175"/>
      <geometry>
        <cylinder length="0.350" radius="0.00635"/>
      </geometry>
    </collision>
    <inertial>
      <origin xyz="0.0 0.0 0.0"/>
      <mass value="4"/>
      <inertia ixx="0.12251344083333332" ixy="0.0" ixz="0.0" iyy="0.12251344083333332" iyz="0.0" izz="0.24499999999999997"/>
    </inertial>
  </link>
  <!-- Spherical Joint 3 -->
  <link name="virtual_link_3_1">
    <inertial>
      <origin xyz="0.0 0.0 0.0"/>
      <mass value="0.1"/>
      <inertia ixx="1.6666666666666667e-06" ixy="0.0" ixz="0.0" iyy="1.6666666666666667e-06" iyz="0.0" izz="1.6666666666666667e-06"/>
    </inertial>
  </link>
  <link name="virtual_link_3_2">
    <inertial>
      <origin xyz="0.0 0.0 0.0"/>
      <mass value="0.1"/>
      <inertia ixx="1.6666666666666667e-06" ixy="0.0" ixz="0.0" iyy="1.6666666666666667e-06" iyz="0.0" izz="1.6666666666666667e-06"/>
    </inertial>
  </link>
  <joint name="arm_forearm_3_1_joint" type="revolute">
    <origin rpy="0.0 0.0 0.0" xyz="-0.190 0.0 0.0"/>
    <parent link="arm_3_link"/>
    <child link="virtual_link_3_1"/>
    <axis xyz="1.0 0.0 0.0"/>
    <limit effort="100.0" lower="-0.41887902047863906" upper="0.41887902047863906" velocity="100.0"/>
  </joint>
  <joint name="arm_forearm_3_2_joint" type="revolute">
    <parent link="virtual_link_3_1"/>
    <child link="virtual_link_3_2"/>
    <axis xyz="0.0 1.0 0.0"/>
    <limit effort="100.0" lower="-3.141592653589793" upper="3.141592653589793" velocity="100.0"/>
  </joint>
  <joint name="arm_forearm_3_3_joint" type="revolute">
    <parent link="virtual_link_3_2"/>
    <child link="forearm_3_link"/>
    <axis xyz="0.0 0.0 1.0"/>
    <limit effort="100.0" lower="-0.41887902047863906" upper="0.41887902047863906" velocity="100.0"/>
  </joint>
  <!-- Mobile Platform -->
  <link name="mobile_platform">
    <visual>
      <geometry>
        <cylinder length="0.00635" radius="0.035"/>
      </geometry>
      <origin xyz="0.0 0.0 -0.003175"/>
      <material name="green">
                
            </material>
    </visual>
    <collision>
      <geometry>
        <cylinder length="0.00635" radius="0.035"/>
      </geometry>
      <origin xyz="0.0 0.0 -0.003175"/>
    </collision>
    <inertial>
      <origin xyz="0.0 0.0 -0.003175"/>
      <mass value="4"/>
      <inertia ixx="0.0012384408333333335" ixy="0.0" ixz="0.0" iyy="0.0012384408333333335" iyz="0.0" izz="0.0024500000000000004"/>
    </inertial>
  </link>
  <!-- Spherical Joint 4 -->
  <link name="virtual_link_1_4">
    <inertial>
      <origin xyz="0.0 0.0 0.0"/>
      <mass value="0.1"/>
      <inertia ixx="1.6666666666666667e-06" ixy="0.0" ixz="0.0" iyy="1.6666666666666667e-06" iyz="0.0" izz="1.6666666666666667e-06"/>
    </inertial>
  </link>
  <link name="virtual_link_1_5">
    <inertial>
      <origin xyz="0.0 0.0 0.0"/>
      <mass value="0.1"/>
      <inertia ixx="1.6666666666666667e-06" ixy="0.0" ixz="0.0" iyy="1.6666666666666667e-06" iyz="0.0" izz="1.6666666666666667e-06"/>
    </inertial>
  </link>
  <joint name="arm_forearm_1_4_joint" type="revolute">
    <origin rpy="0.0 0.0 0.0" xyz="0.0 0.0 0.35635"/>
    <parent link="forearm_1_link"/>
    <child link="virtual_link_1_4"/>
    <axis xyz="1.0 0.0 0.0"/>
    <limit effort="100.0" lower="-0.41887902047863906" upper="0.41887902047863906" velocity="100.0"/>
  </joint>
  <joint name="arm_forearm_1_5_joint" type="revolute">
    <parent link="virtual_link_1_4"/>
    <child link="virtual_link_1_5"/>
    <axis xyz="0.0 1.0 0.0"/>
    <limit effort="100.0" lower="-3.141592653589793" upper="3.141592653589793" velocity="100.0"/>
  </joint>
  <joint name="arm_forearm_1_6_joint" type="revolute">
    <origin xyz="-0.035 0.0 0.0"/>
    <parent link="virtual_link_1_5"/>
    <child link="mobile_platform"/>
    <axis xyz="0.0 0.0 1.0"/>
    <limit effort="100.0" lower="-0.41887902047863906" upper="0.41887902047863906" velocity="100.0"/>
  </joint>
  <!-- Spherical Joint 5 -->
  <link name="virtual_link_2_4">
    <inertial>
      <origin xyz="0.0 0.0 0.0"/>
      <mass value="0.1"/>
      <inertia ixx="1.6666666666666667e-06" ixy="0.0" ixz="0.0" iyy="1.6666666666666667e-06" iyz="0.0" izz="1.6666666666666667e-06"/>
    </inertial>
  </link>
  <link name="virtual_link_2_5">
    <inertial>
      <origin xyz="0.0 0.0 0.0"/>
      <mass value="0.1"/>
      <inertia ixx="1.6666666666666667e-06" ixy="0.0" ixz="0.0" iyy="1.6666666666666667e-06" iyz="0.0" izz="1.6666666666666667e-06"/>
    </inertial>
  </link>
  <joint name="arm_forearm_2_4_joint" type="revolute">
    <origin rpy="0.0 0.0 0.0" xyz="0.0 0.0 0.35635"/>
    <parent link="forearm_2_link"/>
    <child link="virtual_link_2_4"/>
    <axis xyz="1.0 0.0 0.0"/>
    <limit effort="100.0" lower="-0.41887902047863906" upper="0.41887902047863906" velocity="100.0"/>
  </joint>
  <joint name="arm_forearm_2_5_joint" type="revolute">
    <parent link="virtual_link_2_4"/>
    <child link="virtual_link_2_5"/>
    <axis xyz="0.0 1.0 0.0"/>
    <limit effort="100.0" lower="-3.141592653589793" upper="3.141592653589793" velocity="100.0"/>
  </joint>
  <gazebo>
    <joint name="arm_forearm_2_6_joint" type="revolute">
      <origin xyz="-0.0175 0.03031 0.0"/>
      <parent link="mobile_platform"/>
      <child link="virtual_link_2_5"/>
      <axis xyz="0.0 0.0 1.0"/>
      <limit effort="100.0" lower="-0.41887902047863906" upper="0.41887902047863906" velocity="100.0"/>
    </joint>
  </gazebo>
  <gazebo reference="base_link">
    <material>Gazebo/Green</material>
  </gazebo>
  <gazebo>
    <plugin filename="libgazebo_ros_joint_state_publisher.so" name="gazebo_ros_joint_state_publisher">
      <update_rate>20</update_rate>
      <joint_name>base_arm_1_joint</joint_name>
      <joint_name>arm_forearm_1_1_joint</joint_name>
      <joint_name>arm_forearm_1_2_joint</joint_name>
      <joint_name>arm_forearm_1_3_joint</joint_name>
      <joint_name>arm_forearm_1_4_joint</joint_name>
      <joint_name>arm_forearm_1_5_joint</joint_name>
      <joint_name>arm_forearm_1_6_joint</joint_name>
      <joint_name>base_arm_2_joint</joint_name>
      <joint_name>arm_forearm_2_1_joint</joint_name>
      <joint_name>arm_forearm_2_2_joint</joint_name>
      <joint_name>arm_forearm_2_3_joint</joint_name>
      <joint_name>arm_forearm_2_4_joint</joint_name>
      <joint_name>arm_forearm_2_5_joint</joint_name>
      <joint_name>arm_forearm_2_6_joint</joint_name>
      <joint_name>base_arm_3_joint</joint_name>
      <joint_name>arm_forearm_3_1_joint</joint_name>
      <joint_name>arm_forearm_3_2_joint</joint_name>
      <joint_name>arm_forearm_3_3_joint</joint_name>
    </plugin>
  </gazebo>
  <gazebo>
    <plugin filename="libgazebo_ros_joint_pose_trajectory.so" name="gazebo_ros_joint_pose_trajectory">
      <update_rate>20</update_rate>
    </plugin>
  </gazebo>
</robot>
