<?xml version="1.0" ?>
<!-- =================================================================================== -->
<!-- |    This document was autogenerated by xacro from delta.urdf.xacro               | -->
<!-- |    EDITING THIS FILE BY HAND IS NOT RECOMMENDED                                 | -->
<!-- =================================================================================== -->
<robot name="delta">
  <!-- base and end links -->
  <!-- Upper link -->
  <physics type="ode">
    <max_step_size>0.001</max_step_size>
    <real_time_factor>0.1</real_time_factor>
    <real_time_update_rate>1000</real_time_update_rate>
    <gravity>0 0 -9.8</gravity>
  </physics>
  <gazebo>
    <plugin filename="libgazebo_ros2_control.so" name="gazebo_ros2_control">
      <robotNamespace/>
      <robotSimType>gazebo_ros2_control/DefaultRobotHWSim</robotSimType>
    </plugin>
  </gazebo>
  <gazebo reference="base_link">
    <material>Gazebo/Orange</material>
    <selfCollide>false</selfCollide>
  </gazebo>
  <gazebo reference="end_link">
    <material>Gazebo/Orange</material>
    <selfCollide>false</selfCollide>
  </gazebo>
  <transmission name="arm_1_delta_joint_trans">
    <type>transmission_interface/Transmission</type>
    <joint name="arm_1_delta_joint">
      <hardwareInterface>hardware_interface::EffortJoint</hardwareInterface>
    </joint>
    <actuator name="arm_1_delta_joint_motor">
      <hardwareInterface>hardware_interface::EffortJoint</hardwareInterface>
      <mechanicalReduction>1</mechanicalReduction>
    </actuator>
  </transmission>
  <transmission name="arm_2_delta_joint_trans">
    <type>transmission_interface/Transmission</type>
    <joint name="arm_2_delta_joint">
      <hardwareInterface>hardware_interface::EffortJoint</hardwareInterface>
    </joint>
    <actuator name="arm_2_delta_joint_motor">
      <hardwareInterface>hardware_interface::EffortJoint</hardwareInterface>
      <mechanicalReduction>1</mechanicalReduction>
    </actuator>
  </transmission>
  <transmission name="arm_3_delta_joint_trans">
    <type>transmission_interface/Transmission</type>
    <joint name="arm_3_delta_joint">
      <hardwareInterface>hardware_interface::EffortJoint</hardwareInterface>
    </joint>
    <actuator name="arm_3_delta_joint_motor">
      <hardwareInterface>hardware_interface::EffortJoint</hardwareInterface>
      <mechanicalReduction>1</mechanicalReduction>
    </actuator>
  </transmission>
  <!-- Base of the robot -->
  <link name="world"/>
  <joint name="world_base_joint" type="fixed">
    <origin rpy="0.0 0.0 0.0" xyz="1 0.0 0.0"/>
    <parent link="world"/>
    <child link="base_link"/>
  </joint>
  <link name="base_link">
    <visual>
      <origin rpy="0.0 0.0 0.0" xyz="0.0 0.0 0.0"/>
      <geometry>
        <cylinder length="0.0127" radius="0.111"/>
      </geometry>
      <material name="orange">
        <color rgba="1.0 0.4235294117647059 0.0392156862745098 1.0"/>
      </material>
    </visual>
    <collision>
      <origin rpy="0.0 0.0 0.0" xyz="0.0 0.0 0.0"/>
      <geometry>
        <cylinder length="0.0127" radius="0.111"/>
      </geometry>
    </collision>
    <inertial>
      <origin rpy="0.0 0.0 0.0" xyz="0.0 0.0 0.0"/>
      <mass value="12"/>
      <inertia ixx="0.037124290000000004" ixy="0.0" ixz="0.0" iyy="0.037124290000000004" iyz="0.0" izz="0.073926"/>
    </inertial>
  </link>
  <link name="arm_1_link">
    <collision>
      <origin rpy="0 0 0" xyz="0.175 0 0"/>
      <geometry>
        <box size="0.35 0.00635 0.00635"/>
      </geometry>
    </collision>
    <visual>
      <origin rpy="0 0 0" xyz="0.175 0 0"/>
      <geometry>
        <box size="0.35 0.00635 0.00635"/>
      </geometry>
      <material name="black">
        <color rgba="0.0 0.0 0.0 1.0"/>
      </material>
    </visual>
    <inertial>
      <origin rpy="0 0 0" xyz="0 0 0.175"/>
      <mass value="0.02"/>
      <inertia ixx="1.344083333333333e-07" ixy="0.0" ixz="0.0" iyy="0.0002042338708333333" iyz="0.0" izz="0.0002042338708333333"/>
    </inertial>
  </link>
  <joint name="arm_1_joint" type="continuous">
    <parent link="arm_1_link"/>
    <child link="forearm_1_top_link"/>
    <origin rpy="0 0.5235987755982988 0" xyz="0.35 0 0"/>
    <axis xyz="0 1 0"/>
  </joint>
  <link name="forearm_1_top_link">
    <collision>
      <origin rpy="0 0 0" xyz="0 0 0"/>
      <geometry>
        <box size="0.01 0.06 0.01"/>
      </geometry>
    </collision>
    <visual>
      <origin rpy="0 0 0" xyz="0 0 0"/>
      <geometry>
        <box size="0.01 0.06 0.01"/>
      </geometry>
      <material name="grey">
        <color rgba="0.2 0.2 0.2 1.0"/>
      </material>
    </visual>
    <inertial>
      <origin rpy="0 0 0" xyz="0 0 0"/>
      <mass value="0.02"/>
      <inertia ixx="6.1666666666666655e-06" ixy="0.0" ixz="0.0" iyy="3.3333333333333335e-07" iyz="0.0" izz="6.1666666666666655e-06"/>
    </inertial>
  </link>
  <joint name="forearm_1_top_right_joint" type="continuous">
    <parent link="forearm_1_top_link"/>
    <child link="forearm_1_right_link"/>
    <origin rpy="0 0 0" xyz="0 -0.03 0"/>
    <axis xyz="1 0 0"/>
  </joint>
  <link name="forearm_1_right_link">
    <collision>
      <origin rpy="0 0 0" xyz="0 0 -0.25"/>
      <geometry>
        <box size="0.01 0.01 0.5"/>
      </geometry>
    </collision>
    <visual>
      <origin rpy="0 0 0" xyz="0 0 -0.25"/>
      <geometry>
        <box size="0.01 0.01 0.5"/>
      </geometry>
      <material name="grey">
        <color rgba="0.2 0.2 0.2 1.0"/>
      </material>
    </visual>
    <inertial>
      <origin rpy="0 0 0" xyz="0 0 -0.25"/>
      <mass value="0.02"/>
      <inertia ixx="0.0004168333333333333" ixy="0.0" ixz="0.0" iyy="0.0004168333333333333" iyz="0.0" izz="3.3333333333333335e-07"/>
    </inertial>
  </link>
  <joint name="forearm_1_top_left_joint" type="continuous">
    <parent link="forearm_1_top_link"/>
    <child link="forearm_1_left_link"/>
    <origin rpy="0 0 0" xyz="0 0.03 0"/>
    <axis xyz="1 0 0"/>
  </joint>
  <link name="forearm_1_left_link">
    <collision>
      <origin rpy="0 0 0" xyz="0 0 -0.25"/>
      <geometry>
        <box size="0.01 0.01 0.5"/>
      </geometry>
    </collision>
    <visual>
      <origin rpy="0 0 0" xyz="0 0 -0.25"/>
      <geometry>
        <box size="0.01 0.01 0.5"/>
      </geometry>
      <material name="grey">
        <color rgba="0.2 0.2 0.2 1.0"/>
      </material>
    </visual>
    <inertial>
      <origin rpy="0 0 0" xyz="0 0 -0.25"/>
      <mass value="0.02"/>
      <inertia ixx="0.0004168333333333333" ixy="0.0" ixz="0.0" iyy="0.0004168333333333333" iyz="0.0" izz="3.3333333333333335e-07"/>
    </inertial>
  </link>
  <joint name="forearm_1_right_bottom_joint" type="continuous">
    <parent link="forearm_1_right_link"/>
    <child link="forearm_1_bottom_link"/>
    <origin rpy="0 0 0" xyz="0 0 -0.5"/>
    <axis xyz="1 0 0"/>
  </joint>
  <link name="forearm_1_bottom_link">
    <collision>
      <origin rpy="0 0 0" xyz="0 0.03 0"/>
      <geometry>
        <box size="0.01 0.06 0.01"/>
      </geometry>
    </collision>
    <visual>
      <origin rpy="0 0 0" xyz="0 0.03 0"/>
      <geometry>
        <box size="0.01 0.06 0.01"/>
      </geometry>
      <material name="grey">
        <color rgba="0.2 0.2 0.2 1.0"/>
      </material>
    </visual>
    <inertial>
      <origin rpy="0 0 0" xyz="0 0.03 0"/>
      <mass value="0.02"/>
      <inertia ixx="6.1666666666666655e-06" ixy="0.0" ixz="0.0" iyy="3.3333333333333335e-07" iyz="0.0" izz="6.1666666666666655e-06"/>
    </inertial>
  </link>
  <joint name="forearm_1_bottom_end_joint" type="continuous">
    <parent link="forearm_1_bottom_link"/>
    <child link="forearm_1_end_link"/>
    <origin rpy="0 -0.5235987755982988 0" xyz="0 0.03 0"/>
    <axis xyz="0 1 0"/>
  </joint>
  <link name="forearm_1_end_link">
    <collision>
      <origin rpy="0 0 0" xyz="-0.015 0 0"/>
      <geometry>
        <box size="0.03 0.01 0.01"/>
      </geometry>
    </collision>
    <visual>
      <origin rpy="0 0 0" xyz="-0.015 0 0"/>
      <geometry>
        <box size="0.03 0.01 0.01"/>
      </geometry>
      <material name="black">
        <color rgba="0.0 0.0 0.0 1.0"/>
      </material>
    </visual>
    <inertial>
      <origin rpy="0 0 0" xyz="-0.015 0 0"/>
      <mass value="0.02"/>
      <inertia ixx="3.3333333333333335e-07" ixy="0.0" ixz="0.0" iyy="1.6666666666666667e-06" iyz="0.0" izz="1.6666666666666667e-06"/>
    </inertial>
  </link>
  <joint name="forearm_1_bottom_virtual_joint" type="continuous">
    <parent link="forearm_1_bottom_link"/>
    <child link="forearm_1_bottom_virtual_link"/>
    <origin rpy="0 0 0" xyz="0 0.06 0"/>
    <axis xyz="1 0 0"/>
  </joint>
  <link name="forearm_1_bottom_virtual_link">
    <inertial>
      <origin rpy="0 0 0" xyz="0 0 0"/>
      <mass value="0.01"/>
      <inertia ixx="0.001" ixy="0.0" ixz="0.0" iyy="0.001" iyz="0.0" izz="0.001"/>
    </inertial>
  </link>
  <joint name="forearm_1_left_virtual_joint" type="fixed">
    <parent link="forearm_1_left_link"/>
    <child link="forearm_1_left_virtual_link"/>
    <origin rpy="0 0 0" xyz="0 0 -0.5"/>
  </joint>
  <link name="forearm_1_left_virtual_link">
    <inertial>
      <origin rpy="0 0 0" xyz="0 0 0"/>
      <mass value="0.01"/>
      <inertia ixx="0.001" ixy="0.0" ixz="0.0" iyy="0.001" iyz="0.0" izz="0.001"/>
    </inertial>
  </link>
  <gazebo>
    <joint name="forearm_1_left_bottom_joint" type="fixed">
      <parent>forearm_1_left_virtual_link</parent>
      <child>forearm_1_bottom_virtual_link</child>
      <pose> 0 0 0 0 0 0 </pose>
    </joint>
  </gazebo>
  <gazebo reference="arm_1_link">
    <material>Gazebo/Black</material>
    <selfCollide>false</selfCollide>
  </gazebo>
  <gazebo reference="forearm_1_top_link">
    <material>Gazebo/Grey</material>
    <selfCollide>false</selfCollide>
  </gazebo>
  <gazebo reference="forearm_1_right_link">
    <material>Gazebo/Grey</material>
    <selfCollide>false</selfCollide>
  </gazebo>
  <gazebo reference="forearm_1_left_link">
    <material>Gazebo/Grey</material>
    <selfCollide>false</selfCollide>
  </gazebo>
  <gazebo reference="forearm_1_bottom_link">
    <material>Gazebo/Grey</material>
    <selfCollide>false</selfCollide>
  </gazebo>
  <gazebo reference="forearm_1_end_link">
    <material>Gazebo/Black</material>
    <selfCollide>false</selfCollide>
  </gazebo>
  <transmission name="arm_1_joint_trans">
    <type>transmission_interface/Transmission</type>
    <joint name="arm_1_joint">
      <hardwareInterface>hardware_interface::EffortJoint</hardwareInterface>
    </joint>
    <actuator name="arm_1_joint_motor">
      <hardwareInterface>hardware_interface::EffortJoint</hardwareInterface>
      <mechanicalReduction>1</mechanicalReduction>
    </actuator>
  </transmission>
  <transmission name="forearm_1_top_rignt_joint_trans">
    <type>transmission_interface/Transmission</type>
    <joint name="forearm_1_top_rignt_joint">
      <hardwareInterface>hardware_interface::EffortJoint</hardwareInterface>
    </joint>
    <actuator name="forearm_1_top_rignt_joint_motor">
      <hardwareInterface>hardware_interface::EffortJoint</hardwareInterface>
      <mechanicalReduction>1</mechanicalReduction>
    </actuator>
  </transmission>
  <transmission name="forearm_1_top_left_joint_trans">
    <type>transmission_interface/Transmission</type>
    <joint name="forearm_1_top_left_joint">
      <hardwareInterface>hardware_interface::EffortJoint</hardwareInterface>
    </joint>
    <actuator name="forearm_1_top_left_joint_motor">
      <hardwareInterface>hardware_interface::EffortJoint</hardwareInterface>
      <mechanicalReduction>1</mechanicalReduction>
    </actuator>
  </transmission>
  <transmission name="forearm_1_right_bottom_joint_trans">
    <type>transmission_interface/Transmission</type>
    <joint name="forearm_1_right_bottom_joint">
      <hardwareInterface>hardware_interface::EffortJoint</hardwareInterface>
    </joint>
    <actuator name="forearm_1_right_bottom_joint_motor">
      <hardwareInterface>hardware_interface::EffortJoint</hardwareInterface>
      <mechanicalReduction>1</mechanicalReduction>
    </actuator>
  </transmission>
  <transmission name="forearm_1_bottom_end_joint_trans">
    <type>transmission_interface/Transmission</type>
    <joint name="forearm_1_bottom_end_joint">
      <hardwareInterface>hardware_interface::EffortJoint</hardwareInterface>
    </joint>
    <actuator name="forearm_1_bottom_end_joint_motor">
      <hardwareInterface>hardware_interface::EffortJoint</hardwareInterface>
      <mechanicalReduction>1</mechanicalReduction>
    </actuator>
  </transmission>
  <transmission name="forearm_1_bottom_virtual_joint_trans">
    <type>transmission_interface/Transmission</type>
    <joint name="forearm_1_bottom_virtual_joint">
      <hardwareInterface>hardware_interface::EffortJoint</hardwareInterface>
    </joint>
    <actuator name="forearm_1_bottom_virtual_joint_motor">
      <hardwareInterface>hardware_interface::EffortJoint</hardwareInterface>
      <mechanicalReduction>1</mechanicalReduction>
    </actuator>
  </transmission>
  <joint name="arm_1_delta_joint" type="revolute">
    <parent link="base_link"/>
    <child link="arm_1_link"/>
    <origin rpy="0.0 0.0 0.0" xyz="0.111 0.0 0.0"/>
    <axis xyz="0.0 1 0.0"/>
    <dynamics damping="0.7"/>
    <limit effort="6" lower="-0.3490658503988659" upper="1.5707963267948966" velocity="8"/>
  </joint>
  <link name="arm_2_link">
    <collision>
      <origin rpy="0 0 0" xyz="0.175 0 0"/>
      <geometry>
        <box size="0.35 0.00635 0.00635"/>
      </geometry>
    </collision>
    <visual>
      <origin rpy="0 0 0" xyz="0.175 0 0"/>
      <geometry>
        <box size="0.35 0.00635 0.00635"/>
      </geometry>
      <material name="black">
        <color rgba="0.0 0.0 0.0 1.0"/>
      </material>
    </visual>
    <inertial>
      <origin rpy="0 0 0" xyz="0 0 0.175"/>
      <mass value="0.02"/>
      <inertia ixx="1.344083333333333e-07" ixy="0.0" ixz="0.0" iyy="0.0002042338708333333" iyz="0.0" izz="0.0002042338708333333"/>
    </inertial>
  </link>
  <joint name="arm_2_joint" type="continuous">
    <parent link="arm_2_link"/>
    <child link="forearm_2_top_link"/>
    <origin rpy="0 0.5235987755982988 0" xyz="0.35 0 0"/>
    <axis xyz="0 1 0"/>
  </joint>
  <link name="forearm_2_top_link">
    <collision>
      <origin rpy="0 0 0" xyz="0 0 0"/>
      <geometry>
        <box size="0.01 0.06 0.01"/>
      </geometry>
    </collision>
    <visual>
      <origin rpy="0 0 0" xyz="0 0 0"/>
      <geometry>
        <box size="0.01 0.06 0.01"/>
      </geometry>
      <material name="grey">
        <color rgba="0.2 0.2 0.2 1.0"/>
      </material>
    </visual>
    <inertial>
      <origin rpy="0 0 0" xyz="0 0 0"/>
      <mass value="0.02"/>
      <inertia ixx="6.1666666666666655e-06" ixy="0.0" ixz="0.0" iyy="3.3333333333333335e-07" iyz="0.0" izz="6.1666666666666655e-06"/>
    </inertial>
  </link>
  <joint name="forearm_2_top_right_joint" type="continuous">
    <parent link="forearm_2_top_link"/>
    <child link="forearm_2_right_link"/>
    <origin rpy="0 0 0" xyz="0 -0.03 0"/>
    <axis xyz="1 0 0"/>
  </joint>
  <link name="forearm_2_right_link">
    <collision>
      <origin rpy="0 0 0" xyz="0 0 -0.25"/>
      <geometry>
        <box size="0.01 0.01 0.5"/>
      </geometry>
    </collision>
    <visual>
      <origin rpy="0 0 0" xyz="0 0 -0.25"/>
      <geometry>
        <box size="0.01 0.01 0.5"/>
      </geometry>
      <material name="grey">
        <color rgba="0.2 0.2 0.2 1.0"/>
      </material>
    </visual>
    <inertial>
      <origin rpy="0 0 0" xyz="0 0 -0.25"/>
      <mass value="0.02"/>
      <inertia ixx="0.0004168333333333333" ixy="0.0" ixz="0.0" iyy="0.0004168333333333333" iyz="0.0" izz="3.3333333333333335e-07"/>
    </inertial>
  </link>
  <joint name="forearm_2_top_left_joint" type="continuous">
    <parent link="forearm_2_top_link"/>
    <child link="forearm_2_left_link"/>
    <origin rpy="0 0 0" xyz="0 0.03 0"/>
    <axis xyz="1 0 0"/>
  </joint>
  <link name="forearm_2_left_link">
    <collision>
      <origin rpy="0 0 0" xyz="0 0 -0.25"/>
      <geometry>
        <box size="0.01 0.01 0.5"/>
      </geometry>
    </collision>
    <visual>
      <origin rpy="0 0 0" xyz="0 0 -0.25"/>
      <geometry>
        <box size="0.01 0.01 0.5"/>
      </geometry>
      <material name="grey">
        <color rgba="0.2 0.2 0.2 1.0"/>
      </material>
    </visual>
    <inertial>
      <origin rpy="0 0 0" xyz="0 0 -0.25"/>
      <mass value="0.02"/>
      <inertia ixx="0.0004168333333333333" ixy="0.0" ixz="0.0" iyy="0.0004168333333333333" iyz="0.0" izz="3.3333333333333335e-07"/>
    </inertial>
  </link>
  <joint name="forearm_2_right_bottom_joint" type="continuous">
    <parent link="forearm_2_right_link"/>
    <child link="forearm_2_bottom_link"/>
    <origin rpy="0 0 0" xyz="0 0 -0.5"/>
    <axis xyz="1 0 0"/>
  </joint>
  <link name="forearm_2_bottom_link">
    <collision>
      <origin rpy="0 0 0" xyz="0 0.03 0"/>
      <geometry>
        <box size="0.01 0.06 0.01"/>
      </geometry>
    </collision>
    <visual>
      <origin rpy="0 0 0" xyz="0 0.03 0"/>
      <geometry>
        <box size="0.01 0.06 0.01"/>
      </geometry>
      <material name="grey">
        <color rgba="0.2 0.2 0.2 1.0"/>
      </material>
    </visual>
    <inertial>
      <origin rpy="0 0 0" xyz="0 0.03 0"/>
      <mass value="0.02"/>
      <inertia ixx="6.1666666666666655e-06" ixy="0.0" ixz="0.0" iyy="3.3333333333333335e-07" iyz="0.0" izz="6.1666666666666655e-06"/>
    </inertial>
  </link>
  <joint name="forearm_2_bottom_end_joint" type="continuous">
    <parent link="forearm_2_bottom_link"/>
    <child link="forearm_2_end_link"/>
    <origin rpy="0 -0.5235987755982988 0" xyz="0 0.03 0"/>
    <axis xyz="0 1 0"/>
  </joint>
  <link name="forearm_2_end_link">
    <collision>
      <origin rpy="0 0 0" xyz="-0.015 0 0"/>
      <geometry>
        <box size="0.03 0.01 0.01"/>
      </geometry>
    </collision>
    <visual>
      <origin rpy="0 0 0" xyz="-0.015 0 0"/>
      <geometry>
        <box size="0.03 0.01 0.01"/>
      </geometry>
      <material name="black">
        <color rgba="0.0 0.0 0.0 1.0"/>
      </material>
    </visual>
    <inertial>
      <origin rpy="0 0 0" xyz="-0.015 0 0"/>
      <mass value="0.02"/>
      <inertia ixx="3.3333333333333335e-07" ixy="0.0" ixz="0.0" iyy="1.6666666666666667e-06" iyz="0.0" izz="1.6666666666666667e-06"/>
    </inertial>
  </link>
  <joint name="forearm_2_bottom_virtual_joint" type="continuous">
    <parent link="forearm_2_bottom_link"/>
    <child link="forearm_2_bottom_virtual_link"/>
    <origin rpy="0 0 0" xyz="0 0.06 0"/>
    <axis xyz="1 0 0"/>
  </joint>
  <link name="forearm_2_bottom_virtual_link">
    <inertial>
      <origin rpy="0 0 0" xyz="0 0 0"/>
      <mass value="0.01"/>
      <inertia ixx="0.001" ixy="0.0" ixz="0.0" iyy="0.001" iyz="0.0" izz="0.001"/>
    </inertial>
  </link>
  <joint name="forearm_2_left_virtual_joint" type="fixed">
    <parent link="forearm_2_left_link"/>
    <child link="forearm_2_left_virtual_link"/>
    <origin rpy="0 0 0" xyz="0 0 -0.5"/>
  </joint>
  <link name="forearm_2_left_virtual_link">
    <inertial>
      <origin rpy="0 0 0" xyz="0 0 0"/>
      <mass value="0.01"/>
      <inertia ixx="0.001" ixy="0.0" ixz="0.0" iyy="0.001" iyz="0.0" izz="0.001"/>
    </inertial>
  </link>
  <gazebo>
    <joint name="forearm_2_left_bottom_joint" type="fixed">
      <parent>forearm_2_left_virtual_link</parent>
      <child>forearm_2_bottom_virtual_link</child>
      <pose> 0 0 0 0 0 0 </pose>
    </joint>
  </gazebo>
  <gazebo reference="arm_2_link">
    <material>Gazebo/Black</material>
    <selfCollide>false</selfCollide>
  </gazebo>
  <gazebo reference="forearm_2_top_link">
    <material>Gazebo/Grey</material>
    <selfCollide>false</selfCollide>
  </gazebo>
  <gazebo reference="forearm_2_right_link">
    <material>Gazebo/Grey</material>
    <selfCollide>false</selfCollide>
  </gazebo>
  <gazebo reference="forearm_2_left_link">
    <material>Gazebo/Grey</material>
    <selfCollide>false</selfCollide>
  </gazebo>
  <gazebo reference="forearm_2_bottom_link">
    <material>Gazebo/Grey</material>
    <selfCollide>false</selfCollide>
  </gazebo>
  <gazebo reference="forearm_2_end_link">
    <material>Gazebo/Black</material>
    <selfCollide>false</selfCollide>
  </gazebo>
  <transmission name="arm_2_joint_trans">
    <type>transmission_interface/Transmission</type>
    <joint name="arm_2_joint">
      <hardwareInterface>hardware_interface::EffortJoint</hardwareInterface>
    </joint>
    <actuator name="arm_2_joint_motor">
      <hardwareInterface>hardware_interface::EffortJoint</hardwareInterface>
      <mechanicalReduction>1</mechanicalReduction>
    </actuator>
  </transmission>
  <transmission name="forearm_2_top_rignt_joint_trans">
    <type>transmission_interface/Transmission</type>
    <joint name="forearm_2_top_rignt_joint">
      <hardwareInterface>hardware_interface::EffortJoint</hardwareInterface>
    </joint>
    <actuator name="forearm_2_top_rignt_joint_motor">
      <hardwareInterface>hardware_interface::EffortJoint</hardwareInterface>
      <mechanicalReduction>1</mechanicalReduction>
    </actuator>
  </transmission>
  <transmission name="forearm_2_top_left_joint_trans">
    <type>transmission_interface/Transmission</type>
    <joint name="forearm_2_top_left_joint">
      <hardwareInterface>hardware_interface::EffortJoint</hardwareInterface>
    </joint>
    <actuator name="forearm_2_top_left_joint_motor">
      <hardwareInterface>hardware_interface::EffortJoint</hardwareInterface>
      <mechanicalReduction>1</mechanicalReduction>
    </actuator>
  </transmission>
  <transmission name="forearm_2_right_bottom_joint_trans">
    <type>transmission_interface/Transmission</type>
    <joint name="forearm_2_right_bottom_joint">
      <hardwareInterface>hardware_interface::EffortJoint</hardwareInterface>
    </joint>
    <actuator name="forearm_2_right_bottom_joint_motor">
      <hardwareInterface>hardware_interface::EffortJoint</hardwareInterface>
      <mechanicalReduction>1</mechanicalReduction>
    </actuator>
  </transmission>
  <transmission name="forearm_2_bottom_end_joint_trans">
    <type>transmission_interface/Transmission</type>
    <joint name="forearm_2_bottom_end_joint">
      <hardwareInterface>hardware_interface::EffortJoint</hardwareInterface>
    </joint>
    <actuator name="forearm_2_bottom_end_joint_motor">
      <hardwareInterface>hardware_interface::EffortJoint</hardwareInterface>
      <mechanicalReduction>1</mechanicalReduction>
    </actuator>
  </transmission>
  <transmission name="forearm_2_bottom_virtual_joint_trans">
    <type>transmission_interface/Transmission</type>
    <joint name="forearm_2_bottom_virtual_joint">
      <hardwareInterface>hardware_interface::EffortJoint</hardwareInterface>
    </joint>
    <actuator name="forearm_2_bottom_virtual_joint_motor">
      <hardwareInterface>hardware_interface::EffortJoint</hardwareInterface>
      <mechanicalReduction>1</mechanicalReduction>
    </actuator>
  </transmission>
  <joint name="arm_2_delta_joint" type="revolute">
    <parent link="base_link"/>
    <child link="arm_2_link"/>
    <origin rpy="0.0 0.0 -2.0943951023931953" xyz="-0.0555 -0.09612 0.0"/>
    <axis xyz="0.0 1 0.0"/>
    <dynamics damping="0.7"/>
    <limit effort="6" lower="-0.3490658503988659" upper="1.5707963267948966" velocity="8"/>
  </joint>
  <link name="arm_3_link">
    <collision>
      <origin rpy="0 0 0" xyz="0.175 0 0"/>
      <geometry>
        <box size="0.35 0.00635 0.00635"/>
      </geometry>
    </collision>
    <visual>
      <origin rpy="0 0 0" xyz="0.175 0 0"/>
      <geometry>
        <box size="0.35 0.00635 0.00635"/>
      </geometry>
      <material name="black">
        <color rgba="0.0 0.0 0.0 1.0"/>
      </material>
    </visual>
    <inertial>
      <origin rpy="0 0 0" xyz="0 0 0.175"/>
      <mass value="0.02"/>
      <inertia ixx="1.344083333333333e-07" ixy="0.0" ixz="0.0" iyy="0.0002042338708333333" iyz="0.0" izz="0.0002042338708333333"/>
    </inertial>
  </link>
  <joint name="arm_3_joint" type="continuous">
    <parent link="arm_3_link"/>
    <child link="forearm_3_top_link"/>
    <origin rpy="0 0.5235987755982988 0" xyz="0.35 0 0"/>
    <axis xyz="0 1 0"/>
  </joint>
  <link name="forearm_3_top_link">
    <collision>
      <origin rpy="0 0 0" xyz="0 0 0"/>
      <geometry>
        <box size="0.01 0.06 0.01"/>
      </geometry>
    </collision>
    <visual>
      <origin rpy="0 0 0" xyz="0 0 0"/>
      <geometry>
        <box size="0.01 0.06 0.01"/>
      </geometry>
      <material name="grey">
        <color rgba="0.2 0.2 0.2 1.0"/>
      </material>
    </visual>
    <inertial>
      <origin rpy="0 0 0" xyz="0 0 0"/>
      <mass value="0.02"/>
      <inertia ixx="6.1666666666666655e-06" ixy="0.0" ixz="0.0" iyy="3.3333333333333335e-07" iyz="0.0" izz="6.1666666666666655e-06"/>
    </inertial>
  </link>
  <joint name="forearm_3_top_right_joint" type="continuous">
    <parent link="forearm_3_top_link"/>
    <child link="forearm_3_right_link"/>
    <origin rpy="0 0 0" xyz="0 -0.03 0"/>
    <axis xyz="1 0 0"/>
  </joint>
  <link name="forearm_3_right_link">
    <collision>
      <origin rpy="0 0 0" xyz="0 0 -0.25"/>
      <geometry>
        <box size="0.01 0.01 0.5"/>
      </geometry>
    </collision>
    <visual>
      <origin rpy="0 0 0" xyz="0 0 -0.25"/>
      <geometry>
        <box size="0.01 0.01 0.5"/>
      </geometry>
      <material name="grey">
        <color rgba="0.2 0.2 0.2 1.0"/>
      </material>
    </visual>
    <inertial>
      <origin rpy="0 0 0" xyz="0 0 -0.25"/>
      <mass value="0.02"/>
      <inertia ixx="0.0004168333333333333" ixy="0.0" ixz="0.0" iyy="0.0004168333333333333" iyz="0.0" izz="3.3333333333333335e-07"/>
    </inertial>
  </link>
  <joint name="forearm_3_top_left_joint" type="continuous">
    <parent link="forearm_3_top_link"/>
    <child link="forearm_3_left_link"/>
    <origin rpy="0 0 0" xyz="0 0.03 0"/>
    <axis xyz="1 0 0"/>
  </joint>
  <link name="forearm_3_left_link">
    <collision>
      <origin rpy="0 0 0" xyz="0 0 -0.25"/>
      <geometry>
        <box size="0.01 0.01 0.5"/>
      </geometry>
    </collision>
    <visual>
      <origin rpy="0 0 0" xyz="0 0 -0.25"/>
      <geometry>
        <box size="0.01 0.01 0.5"/>
      </geometry>
      <material name="grey">
        <color rgba="0.2 0.2 0.2 1.0"/>
      </material>
    </visual>
    <inertial>
      <origin rpy="0 0 0" xyz="0 0 -0.25"/>
      <mass value="0.02"/>
      <inertia ixx="0.0004168333333333333" ixy="0.0" ixz="0.0" iyy="0.0004168333333333333" iyz="0.0" izz="3.3333333333333335e-07"/>
    </inertial>
  </link>
  <joint name="forearm_3_right_bottom_joint" type="continuous">
    <parent link="forearm_3_right_link"/>
    <child link="forearm_3_bottom_link"/>
    <origin rpy="0 0 0" xyz="0 0 -0.5"/>
    <axis xyz="1 0 0"/>
  </joint>
  <link name="forearm_3_bottom_link">
    <collision>
      <origin rpy="0 0 0" xyz="0 0.03 0"/>
      <geometry>
        <box size="0.01 0.06 0.01"/>
      </geometry>
    </collision>
    <visual>
      <origin rpy="0 0 0" xyz="0 0.03 0"/>
      <geometry>
        <box size="0.01 0.06 0.01"/>
      </geometry>
      <material name="grey">
        <color rgba="0.2 0.2 0.2 1.0"/>
      </material>
    </visual>
    <inertial>
      <origin rpy="0 0 0" xyz="0 0.03 0"/>
      <mass value="0.02"/>
      <inertia ixx="6.1666666666666655e-06" ixy="0.0" ixz="0.0" iyy="3.3333333333333335e-07" iyz="0.0" izz="6.1666666666666655e-06"/>
    </inertial>
  </link>
  <joint name="forearm_3_bottom_end_joint" type="continuous">
    <parent link="forearm_3_bottom_link"/>
    <child link="forearm_3_end_link"/>
    <origin rpy="0 -0.5235987755982988 0" xyz="0 0.03 0"/>
    <axis xyz="0 1 0"/>
  </joint>
  <link name="forearm_3_end_link">
    <collision>
      <origin rpy="0 0 0" xyz="-0.015 0 0"/>
      <geometry>
        <box size="0.03 0.01 0.01"/>
      </geometry>
    </collision>
    <visual>
      <origin rpy="0 0 0" xyz="-0.015 0 0"/>
      <geometry>
        <box size="0.03 0.01 0.01"/>
      </geometry>
      <material name="black">
        <color rgba="0.0 0.0 0.0 1.0"/>
      </material>
    </visual>
    <inertial>
      <origin rpy="0 0 0" xyz="-0.015 0 0"/>
      <mass value="0.02"/>
      <inertia ixx="3.3333333333333335e-07" ixy="0.0" ixz="0.0" iyy="1.6666666666666667e-06" iyz="0.0" izz="1.6666666666666667e-06"/>
    </inertial>
  </link>
  <joint name="forearm_3_bottom_virtual_joint" type="continuous">
    <parent link="forearm_3_bottom_link"/>
    <child link="forearm_3_bottom_virtual_link"/>
    <origin rpy="0 0 0" xyz="0 0.06 0"/>
    <axis xyz="1 0 0"/>
  </joint>
  <link name="forearm_3_bottom_virtual_link">
    <inertial>
      <origin rpy="0 0 0" xyz="0 0 0"/>
      <mass value="0.01"/>
      <inertia ixx="0.001" ixy="0.0" ixz="0.0" iyy="0.001" iyz="0.0" izz="0.001"/>
    </inertial>
  </link>
  <joint name="forearm_3_left_virtual_joint" type="fixed">
    <parent link="forearm_3_left_link"/>
    <child link="forearm_3_left_virtual_link"/>
    <origin rpy="0 0 0" xyz="0 0 -0.5"/>
  </joint>
  <link name="forearm_3_left_virtual_link">
    <inertial>
      <origin rpy="0 0 0" xyz="0 0 0"/>
      <mass value="0.01"/>
      <inertia ixx="0.001" ixy="0.0" ixz="0.0" iyy="0.001" iyz="0.0" izz="0.001"/>
    </inertial>
  </link>
  <gazebo>
    <joint name="forearm_3_left_bottom_joint" type="fixed">
      <parent>forearm_3_left_virtual_link</parent>
      <child>forearm_3_bottom_virtual_link</child>
      <pose> 0 0 0 0 0 0 </pose>
    </joint>
  </gazebo>
  <gazebo reference="arm_3_link">
    <material>Gazebo/Black</material>
    <selfCollide>false</selfCollide>
  </gazebo>
  <gazebo reference="forearm_3_top_link">
    <material>Gazebo/Grey</material>
    <selfCollide>false</selfCollide>
  </gazebo>
  <gazebo reference="forearm_3_right_link">
    <material>Gazebo/Grey</material>
    <selfCollide>false</selfCollide>
  </gazebo>
  <gazebo reference="forearm_3_left_link">
    <material>Gazebo/Grey</material>
    <selfCollide>false</selfCollide>
  </gazebo>
  <gazebo reference="forearm_3_bottom_link">
    <material>Gazebo/Grey</material>
    <selfCollide>false</selfCollide>
  </gazebo>
  <gazebo reference="forearm_3_end_link">
    <material>Gazebo/Black</material>
    <selfCollide>false</selfCollide>
  </gazebo>
  <transmission name="arm_3_joint_trans">
    <type>transmission_interface/Transmission</type>
    <joint name="arm_3_joint">
      <hardwareInterface>hardware_interface::EffortJoint</hardwareInterface>
    </joint>
    <actuator name="arm_3_joint_motor">
      <hardwareInterface>hardware_interface::EffortJoint</hardwareInterface>
      <mechanicalReduction>1</mechanicalReduction>
    </actuator>
  </transmission>
  <transmission name="forearm_3_top_rignt_joint_trans">
    <type>transmission_interface/Transmission</type>
    <joint name="forearm_3_top_rignt_joint">
      <hardwareInterface>hardware_interface::EffortJoint</hardwareInterface>
    </joint>
    <actuator name="forearm_3_top_rignt_joint_motor">
      <hardwareInterface>hardware_interface::EffortJoint</hardwareInterface>
      <mechanicalReduction>1</mechanicalReduction>
    </actuator>
  </transmission>
  <transmission name="forearm_3_top_left_joint_trans">
    <type>transmission_interface/Transmission</type>
    <joint name="forearm_3_top_left_joint">
      <hardwareInterface>hardware_interface::EffortJoint</hardwareInterface>
    </joint>
    <actuator name="forearm_3_top_left_joint_motor">
      <hardwareInterface>hardware_interface::EffortJoint</hardwareInterface>
      <mechanicalReduction>1</mechanicalReduction>
    </actuator>
  </transmission>
  <transmission name="forearm_3_right_bottom_joint_trans">
    <type>transmission_interface/Transmission</type>
    <joint name="forearm_3_right_bottom_joint">
      <hardwareInterface>hardware_interface::EffortJoint</hardwareInterface>
    </joint>
    <actuator name="forearm_3_right_bottom_joint_motor">
      <hardwareInterface>hardware_interface::EffortJoint</hardwareInterface>
      <mechanicalReduction>1</mechanicalReduction>
    </actuator>
  </transmission>
  <transmission name="forearm_3_bottom_end_joint_trans">
    <type>transmission_interface/Transmission</type>
    <joint name="forearm_3_bottom_end_joint">
      <hardwareInterface>hardware_interface::EffortJoint</hardwareInterface>
    </joint>
    <actuator name="forearm_3_bottom_end_joint_motor">
      <hardwareInterface>hardware_interface::EffortJoint</hardwareInterface>
      <mechanicalReduction>1</mechanicalReduction>
    </actuator>
  </transmission>
  <transmission name="forearm_3_bottom_virtual_joint_trans">
    <type>transmission_interface/Transmission</type>
    <joint name="forearm_3_bottom_virtual_joint">
      <hardwareInterface>hardware_interface::EffortJoint</hardwareInterface>
    </joint>
    <actuator name="forearm_3_bottom_virtual_joint_motor">
      <hardwareInterface>hardware_interface::EffortJoint</hardwareInterface>
      <mechanicalReduction>1</mechanicalReduction>
    </actuator>
  </transmission>
  <joint name="arm_3_delta_joint" type="revolute">
    <parent link="base_link"/>
    <child link="arm_3_link"/>
    <origin rpy="0.0 0.0 2.0943951023931953" xyz="-0.0555 0.09612 0.0"/>
    <axis xyz="0.0 1 0.0"/>
    <dynamics damping="0.7"/>
    <limit effort="6" lower="-0.3490658503988659" upper="1.5707963267948966" velocity="8"/>
  </joint>
</robot>
